Workbook

Sheet Sheet1
A1: Units: pp,: mg/L; ppb: ug/L; ppt: ng/L
A2: MOFs name | C2: Metal ion | D2: Organic ligand | E2: CSD refcode | F2: CCDC number | G2: MOF dosage(g/L) | H2: Higest removal and/or capacity achieved from aquoeus PFAS concentrations of | I2: pH | J2: PFOA adsoption kinetics (time to attain saturation /equilibrium loading) | K2: Adsorption capacity (mg/g) | L2: Removal performance (%) | M2: Regeneration solvents | N2: Regeneration performance | O2: Reference | P2: CAS Number for ligands
A3: Zr(IV) MOFs
A4: UiO-66 | B4: =VLOOKUP(A4,'Zeo++'!$A$2:$A$24,1,FALSE) -> UiO-66 | C4: Zr(IV) | D4: Benzene-1,4-dicarboxylic acid | E4: RUBTAK03 | F4: 1018045 | G4: 0.4 | H4: 2 μg/L | I4: 6.5 | J4: 30 min | K4: N/M | L4: 92 | M4: methanol + 1% NaCl (70–30 v/v) | N4: 83% removal after 5 cycles | O4: https://advanced.onlinelibrary.wiley.com/doi/full/10.1002/adma.202413120 | P4: 100-21-0
A5: UiO-66-5 | B5: =VLOOKUP(A5,'Zeo++'!$A$2:$A$24,1,FALSE) -> #N/A | C5: Zr(IV) | D5: Benzene-1,4-dicarboxylic acid | E5: N/A | F5: N/A | G5: 1 | H5: 2 μg/L | I5: 4 | J5: 30 min | K5: N/M | L5: 87 | M5: 0.4%(v/v) ammonia/methanol | N5: 82% removal after 5 cycles | O5: Dual-functional metal-organic frameworks for adsorptive removal and ultra-trace quantitation of 50 per- and polyfluoroalkyl substances in water - ScienceDirect | P5: 100-21-0
A6: UiO-66-10 | B6: =VLOOKUP(A6,'Zeo++'!$A$2:$A$24,1,FALSE) -> #N/A | C6: Zr(IV) | D6: Benzene-1,4-dicarboxylic acid | E6: N/A | F6: N/A | G6: 1 | H6: 2 μg/L | I6: 4 | J6: 30 min | K6: N/M | L6: 78 | M6: 0.4%(v/v) ammonia/methanol | N6: N/M | O6: Dual-functional metal-organic frameworks for adsorptive removal and ultra-trace quantitation of 50 per- and polyfluoroalkyl substances in water - ScienceDirect | P6: 100-21-0
A7: UiO-66-25 | B7: =VLOOKUP(A7,'Zeo++'!$A$2:$A$24,1,FALSE) -> #N/A | C7: Zr(IV) | D7: Benzene-1,4-dicarboxylic acid | E7: N/A | F7: N/A | G7: 1 | H7: 2 μg/L | I7: 4 | J7: 30 min | K7: N/M | L7: 77 | M7: 0.4%(v/v) ammonia/methanol | N7: N/M | O7: Dual-functional metal-organic frameworks for adsorptive removal and ultra-trace quantitation of 50 per- and polyfluoroalkyl substances in water - ScienceDirect | P7: 100-21-1
A8: UiO-66-NH2 | B8: =VLOOKUP(A8,'Zeo++'!$A$2:$A$24,1,FALSE) -> UiO-66-NH2 | C8: Zr(IV) | D8: 2-amino-1,4-benzenedicarboxylic acid | E8: SURKAT | F8: 1405751 | G8: 0.4 | H8: 2 μg/L | I8: 6.5 | J8: 30 min | K8: N/M | L8: 45 | M8: methanol + 1% NaCl (70–30 v/v) | N8: N/M | O8: https://advanced.onlinelibrary.wiley.com/doi/full/10.1002/adma.202413120 | P8: 10312-55-7
A9: UiO-66-NO2 | B9: =VLOOKUP(A9,'Zeo++'!$A$2:$A$24,1,FALSE) -> #N/A | C9: Zr(IV) | D9: 2-nitroterephthalic acid | E9: SURKEX | F9: 1405752 | G9: 0.4 | H9: 2 μg/L | I9: 6.5 | J9: 30 min | K9: N/M | L9: 41 | M9: methanol + 1% NaCl (70–30 v/v) | N9: N/M | O9: https://advanced.onlinelibrary.wiley.com/doi/full/10.1002/adma.202413121 | P9: 610-29-7
A10: UiO-66-F4 | B10: =VLOOKUP(A10,'Zeo++'!$A$2:$A$24,1,FALSE) -> UiO-66-F4 | C10: Zr(IV) | D10: 2,3,5,6-tetrafluoroterephthalic acid | E10: N/A | F10: N/A | G10: 0.4 | H10: 2 μg/L | I10: 6.5 | J10: 30 min | K10: N/M | L10: 68 | M10: methanol + 1% NaCl (70–30 v/v) | N10: 66% removal after 5 cycles | O10: https://advanced.onlinelibrary.wiley.com/doi/full/10.1002/adma.202413122 | P10: 652-36-8
A11: UiO-67 | B11: =VLOOKUP(A11,'Zeo++'!$A$2:$A$24,1,FALSE) -> UiO-67 | C11: Zr(IV) | D11: Biphenyl-4,4′-dicarboxylic acid | E11: WIZMAV | F11: 960486 | G11: 1 | H11: 1000 mg/L | I11: 3 | J11: N/M | K11: 872 | L11: N/M | M11: N/M | N11: N/M | O11: A fluorinated zirconium-based metal–organic framework as a platform for the capture and removal of perfluorinated pollutants from air and water - Journal of Materials Chemistry A (RSC Publishing) | P11: 787-70-2
A12: UiO-67-F2 | B12: =VLOOKUP(A12,'Zeo++'!$A$2:$A$24,1,FALSE) -> UiO-67-F2 | C12: Zr(IV) | D12: Bifluorinated biphenyl dicarboxylic acid | E12: N/A | F12: N/A | G12: 1 | H12: 1000 mg/L | I12: 3 | J12: N/M | K12: 928 | L12: N/M | M12: N/M | N12: N/M | O12: A fluorinated zirconium-based metal–organic framework as a platform for the capture and removal of perfluorinated pollutants from air and water - Journal of Materials Chemistry A (RSC Publishing) | P12: 224960-60-5
A13: MOF-808 | B13: =VLOOKUP(A13,'Zeo++'!$A$2:$A$24,1,FALSE) -> MOF-808 | C13: Zr(IV) | D13: Trimesic acid | E13: BOHWUS | F13: 1002672 | G13: 1 | H13: 800 mg/L | I13: N/M | J13: N/M | K13: 986 | L13: 36 | M13: N/M | N13: N/M | O13: Chemically Tailored Metal‐Organic Frameworks for Enhanced Capture of Short‐ and Long‐Chain Per‐ and Polyfluoroalkyl Substances from Water - Loukopoulos - 2024 - Advanced Functional Materials - Wiley Online Library | P13: 554-95-0
A14: PCN-999 | B14: =VLOOKUP(A14,'Zeo++'!$A$2:$A$24,1,FALSE) -> PCN-999 | C14: Zr(IV) | D14: 4′,4″′-(2,2-bis(4-carboxyphenyl)ethene- 1,1-diyl)bis(([1,1′-biphenyl]-4-carboxylic acid)) | E14: LONGUU | F14: 2304331 | G14: 1 | H14: 1000 mg/L | I14: N/M | J14: 12 h | K14: 764 | L14: 99 | M14: methanol | N14: 94% removal after 10 cycles | O14: Exceptionally High Perfluorooctanoic Acid Uptake in Water by a Zirconium-Based Metal–Organic Framework through Synergistic Chemical and Physical Adsorption | Journal of the American Chemical Society | P14: Synthetic ligand
A15: PCN-1002 | B15: =VLOOKUP(A15,'Zeo++'!$A$2:$A$24,1,FALSE) -> PCN-1002 | C15: Zr(IV) | D15: 4′,4‴,4″‴,4′‴‴-(ethene-1,1,2,2-tetrayl) tetrakis(3-hydroxy-[1,1′-biphenyl]−4-carboxylic acid) | E15: MUNJEO | F15: 2322790 | G15: 1 | H15: 1000 mg/L | I15: N/M | J15: 9 h | K15: 632 | L15: 81 | M15: methanol and formic acid | N15: 90% removal after 5 cycles | O15: Zirconium‐Based Metal–Organic Frameworks with Free Hydroxy Groups for Enhanced Perfluorooctanoic Acid Uptake in Water - Liang - 2024 - Advanced Materials - Wiley Online Library | P15: Synthetic ligand
A16: DUT-67 | B16: =VLOOKUP(A16,'Zeo++'!$A$2:$A$24,1,FALSE) -> DUT-67 | C16: Zr(IV) | D16: 2,5-thiophenedicarboxylic acid | E16: FIJPAT | F16: 2255747 | G16: 1 | H16: 500 mg/L | I16: N/M | J16: N/M | K16: 382.5 | L16: 28 | M16: N/M | N16: N/M | O16: Chemically Tailored Metal‐Organic Frameworks for Enhanced Capture of Short‐ and Long‐Chain Per‐ and Polyfluoroalkyl Substances from Water - Loukopoulos - 2024 - Advanced Functional Materials - Wiley Online Library | P16: 4282-31-9
A17: NU-1000 | B17: =VLOOKUP(A17,'Zeo++'!$A$2:$A$24,1,FALSE) -> NU-1000 | C17: Zr(IV) | D17: 1,3,6,8-tetrakis(p-benzoic acid)pyrene | E17: FIFFUX | F17: 955328 | G17: 1 | H17: 87 μg/L | I17: N/M | J17: 30min | K17: 507 | L17: 98 | M17: 30/70 v/v 0.1 M HCl/methanol | N17: 96% removal after 5 cycles | O17: Efficient Removal of Per- and Polyfluoroalkyl Substances from Water with Zirconium-Based Metal–Organic Frameworks | Chemistry of Materials | P17: 933047-52-0
A18: Al(III) MOFs
A19: MIL-53(Al)-as | B19: =VLOOKUP(A19,'Zeo++'!$A$2:$A$24,1,FALSE) -> MIL-53(Al)-as | C19: Al(III) | D19: Benzene-1,4-dicarboxylic acid | E19: HEJPAR | F19: 2179625 | G19: 0.5 | H19: 60 mg/L | I19: 7 | J19: 4 h | K19: 4.9 | L19: N/M | M19: 2mM NaOH | N19: N/M | O19: Enhanced removal of perfluorooctanoic acid by aluminum-based metal–organic frameworks prepared by bauxite residue - ScienceDirect | P19: 100-21-0
A20: MIL-96(Al) | B20: =VLOOKUP(A20,'Zeo++'!$A$2:$A$24,1,FALSE) -> MIL-96(Al) | C20: Al(III) | D20: Trimesic acid | E20: WEVYEE | F20: 1558833 | G20: 0.5 | H20: 60 mg/L | I20: 7 | J20: 4 h | K20: 30.64 | L20: N/M | M20: 2mM NaOH | N20: N/M | O20: Enhanced removal of perfluorooctanoic acid by aluminum-based metal–organic frameworks prepared by bauxite residue - ScienceDirect | P20: 554-95-0
A21: MIL-100(Al) | B21: =VLOOKUP(A21,'Zeo++'!$A$2:$A$24,1,FALSE) -> MIL-100(Al) | C21: Al(III) | D21: Trimesic acid | E21: BUSPIP | F21: 789872 | G21: 0.5 | H21: 60 mg/L | I21: 7 | J21: 4 h | K21: 111.07 | L21: N/M | M21: 2mM NaOH | N21: 70.4% removal after 4 cycles | O21: Enhanced removal of perfluorooctanoic acid by aluminum-based metal–organic frameworks prepared by bauxite residue - ScienceDirect | P21: 554-95-0
A22: DUT-5-2 | B22: =VLOOKUP(A22,'Zeo++'!$A$2:$A$24,1,FALSE) -> #N/A | C22: Al(III) | D22: Biphenyl-4,4 -dicarboxylic acid | E22: N/A | F22: N/A | G22: 0.1 | H22: 30 mg/L | I22: 3 | J22: 10 h | K22: 473.7 | L22: 60.9 | M22: Methanol | N22: 66.6% removal after 4 cycles | O22: Microwave synthesis of metal-organic frameworks absorbents (DUT-5-2) for the removal of PFOS and PFOA from aqueous solutions - ScienceDirect | P22: 787-70-2
A23: Cr(III) MOFs
A24: MIL-101(Cr) | B24: =VLOOKUP(A24,'Zeo++'!$A$2:$A$24,1,FALSE) -> MIL-101(Cr) | C24: Cr(III) | D24: Terephthalic acid | E24: OCUNAC | F24: 605510 | G24: 0.05 | H24: 10 mg/L | I24: 5 | J24: 30 min | K24: 12.3 | L24: 13.4 | M24: N/M | N24: 5% removal after 7 cycles | O24: Effectiveness of waste-derived MIL type MOFs in removing PFOA and PFAS pollutants for environmental remediation | Scientific Reports | P24: 100-21-0
A25: MIL-101(Cr)-NH2 | B25: =VLOOKUP(A25,'Zeo++'!$A$2:$A$24,1,FALSE) -> MIL-101(Cr)-NH2 | C25: Cr(III) | D25: 2-amino-1,4-benzenedicarboxylic acid | E25: N/A | F25: N/A | G25: 0.1 | H25: 1000 mg/L | I25: 5 | J25: 60 min | K25: 290 | L25: N/M | M25: N/M | N25: N/M | O25: Understanding the Adsorption of PFOA on MIL-101(Cr)-Based Anionic-Exchange Metal–Organic Frameworks: Comparing DFT Calculations with Aqueous Sorption Experiments | Environmental Science & Technology | P25: 10312-55-7
A26: MIL-101(Cr)-QDMEN | B26: =VLOOKUP(A26,'Zeo++'!$A$2:$A$24,1,FALSE) -> #N/A | C26: Cr(III) | D26: Terephthalic acid | E26: N/A | F26: N/A | G26: 0.1 | H26: 1000 mg/L | I26: 5 | J26: 60 min | K26: 754 | L26: N/M | M26: methanol + 1% NaCl (70–30 v/v) | N26: 90% removal after 3 cycles | O26: Understanding the Adsorption of PFOA on MIL-101(Cr)-Based Anionic-Exchange Metal–Organic Frameworks: Comparing DFT Calculations with Aqueous Sorption Experiments | Environmental Science & Technology | P26: 100-21-0
A27: MIL-101(Cr)-DMEN | B27: =VLOOKUP(A27,'Zeo++'!$A$2:$A$24,1,FALSE) -> #N/A | C27: Cr(III) | D27: Terephthalic acid | E27: N/A | F27: N/A | G27: 0.1 | H27: 1000 mg/L | I27: 5 | J27: 60 min | K27: 534 | L27: N/M | M27: N/M | N27: N/M | O27: Understanding the Adsorption of PFOA on MIL-101(Cr)-Based Anionic-Exchange Metal–Organic Frameworks: Comparing DFT Calculations with Aqueous Sorption Experiments | Environmental Science & Technology | P27: 100-21-0
A28: MIL-101(Cr)-NMe3 | B28: =VLOOKUP(A28,'Zeo++'!$A$2:$A$24,1,FALSE) -> #N/A | C28: Cr(III) | D28: Terephthalic acid | E28: N/A | F28: N/A | G28: 0.1 | H28: 1000 mg/L | I28: 5 | J28: 60 min | K28: 493 | L28: N/M | M28: N/M | N28: N/M | O28: Understanding the Adsorption of PFOA on MIL-101(Cr)-Based Anionic-Exchange Metal–Organic Frameworks: Comparing DFT Calculations with Aqueous Sorption Experiments | Environmental Science & Technology | P28: 100-21-0
A29: Fe(III) MOFs
A30: MIL-100 (Fe) | B30: =VLOOKUP(A30,'Zeo++'!$A$2:$A$24,1,FALSE) -> MIL-100 (Fe) | C30: Fe(III) | D30: Trimesic acid | E30: CIGXIA | F30: 640536 | G30: 1 | H30: 1000 mg/L | I30: 3.3 | J30: 120 min | K30: 427 | L30: N/M | M30: N/M | N30: N/M | O30: Insights to perfluorooctanoic acid adsorption micro-mechanism over Fe-based metal organic frameworks: Combining computational calculation with response surface methodology - ScienceDirect | P30: 554-95-0
A31: MIL-101 (Fe) | B31: =VLOOKUP(A31,'Zeo++'!$A$2:$A$24,1,FALSE) -> MIL-101 (Fe) | C31: Fe(III) | D31: Terephthalic acid | E31: OCUNAC | F31: 605510 | G31: 1 | H31: 1000 mg/L | I31: 3.3 | J31: 120 min | K31: 490 | L31: N/M | M31: N/M | N31: N/M | O31: Insights to perfluorooctanoic acid adsorption micro-mechanism over Fe-based metal organic frameworks: Combining computational calculation with response surface methodology - ScienceDirect | P31: 100-21-0
A32: Zn(II) MOFs
A33: ZIF-7 | B33: =VLOOKUP(A33,'Zeo++'!$A$2:$A$24,1,FALSE) -> ZIF-7 | C33: Zn(II) | D33: Benzimidazole | E33: QOVXAC | F33: 1036075 | G33: 0.2 | H33: 207 mg/L | I33: 5 | J33: 60 min | K33: 22 | L33: N/M | M33: N/M | N33: N/M | O33: Influence of crystal topology and interior surface functionality of metal-organic frameworks on PFOA sorption performance - ScienceDirect | P33: 51-17-2
A34: ZIF-8 | B34: =VLOOKUP(A34,'Zeo++'!$A$2:$A$24,1,FALSE) -> ZIF-8 | C34: Zn(II) | D34: 2-methylimidazole | E34: CUBYAD | F34: 2353474 | G34: 0.2 | H34: 207 mg/L | I34: 5 | J34: 60 min | K34: 177 | L34: N/M | M34: N/M | N34: N/M | O34: Influence of crystal topology and interior surface functionality of metal-organic frameworks on PFOA sorption performance - ScienceDirect | P34: 693-98-1
A35: ZIF-8A-61% | B35: =VLOOKUP(A35,'Zeo++'!$A$2:$A$24,1,FALSE) -> #N/A | C35: Zn(II) | D35: 2-methylimidazole | E35: N/A | F35: N/A | G35: 1 | H35: 2 μg/L | I35: 4 | J35: 30 min | K35: N/M | L35: 77 | M35: 0.4%(v/v) ammonia/methanol | N35: N/M | O35: https://www.sciencedirect.com/science/article/pii/S030438942501595X#sec0050 | P35: 693-98-1
A36: ZIF-8A-SO3H | B36: =VLOOKUP(A36,'Zeo++'!$A$2:$A$24,1,FALSE) -> #N/A | C36: Zn(II) | D36: 2-methylimidazole | E36: N/A | F36: N/A | G36: 1 | H36: 2 μg/L | I36: 4 | J36: 30 min | K36: N/M | L36: 85 | M36: 0.4%(v/v) ammonia/methanol | N36: N/M | O36: https://www.sciencedirect.com/science/article/pii/S030438942501595X#sec0050 | P36: 693-98-1
A37: ZIF-L | B37: =VLOOKUP(A37,'Zeo++'!$A$2:$A$24,1,FALSE) -> ZIF-L | C37: Zn(II) | D37: 2-methylimidazole | E37: IWOZOL | F37: 1509273 | G37: 0.2 | H37: 207 mg/L | I37: 5 | J37: 60 min | K37: 244 | L37: N/M | M37: N/M | N37: N/M | O37: Influence of crystal topology and interior surface functionality of metal-organic frameworks on PFOA sorption performance - ScienceDirect | P37: 693-98-1
A38: Ni(II) MOFs
A39: NiL1-F | B39: =VLOOKUP(A39,'Zeo++'!$A$2:$A$24,1,FALSE) -> #N/A | C39: Ni(II) | D39: Boc2L1-F | E39: N/A | F39: N/A | G39: 0.1 | H39: 1 mg/L | I39: N/M | J39: 12 h | K39: 268.5 | L39: 90.1 | M39: methanol | N39: 82% removal after 4 cycles | O39: https://pubs.acs.org/doi/10.1021/acsami.3c07568?src=getftr&utm_source=wiley&getft_integrator=wiley | P39: Synthetic ligand
A40: NiL1-CCH | B40: =VLOOKUP(A40,'Zeo++'!$A$2:$A$24,1,FALSE) -> #N/A | C40: Ni(II) | D40: Boc2L1-CCH | E40: N/A | F40: N/A | G40: 0.1 | H40: 2 mg/L | I40: N/M | J40: 12 h | K40: 109.2 | L40: 40.2 | M40: methanol | N40: N/M | O40: https://pubs.acs.org/doi/10.1021/acsami.3c07568?src=getftr&utm_source=wiley&getft_integrator=wiley | P40: Synthetic ligand
...

Sheet Zeo++
A2: UiO-66 | B2: =A2=C2 -> TRUE | C2: UiO-66
A3: UiO-66-NH2 | B3: =A3=C3 -> TRUE | C3: UiO-66-NH2
A4: UiO-66-F4 | B4: =A4=C4 -> TRUE | C4: UiO-66-F4
A5: UiO-67 | B5: =A5=C5 -> TRUE | C5: UiO-67
A6: UiO-67-F2 | B6: =A6=C6 -> TRUE | C6: UiO-67-F2
A7: MOF-808 | B7: =A7=C7 -> TRUE | C7: MOF-808
A8: PCN-999 | B8: =A8=C8 -> TRUE | C8: PCN-999
A9: PCN-1002 | B9: =A9=C9 -> TRUE | C9: PCN-1002
A10: DUT-67 | B10: =A10=C10 -> TRUE | C10: DUT-67
A11: NU-1000 | B11: =A11=C11 -> TRUE | C11: NU-1000
A12: MIL-53(Al)-as | B12: =A12=C12 -> TRUE | C12: MIL-53(Al)-as
A13: MIL-96(Al) | B13: =A13=C13 -> TRUE | C13: MIL-96(Al)
... A24: Ce-BTC | B24: =A24=C24 -> TRUE | C24: Ce-BTC
