Workbook

Sheet Training Results
A1: Training 1 - OCSVM | N1: Training 2 - SVM
A2: Serial | B2: Rank | C2: Name | D2: Density | E2: PLD | F2: LCD | G2: GSA | H2: Void_Fraction | I2: Pore_Volume | J2: ocsvm_score | K2: ocsvm_label | N2: Serial | O2: Rank | P2: PrevRank | Q2: Name | R2: Density | S2: PLD | T2: LCD | U2: GSA | V2: Void_Fraction | W2: Pore_Volume | X2: Label | Y2: svm_score | Z2: svm_label
A3: 18 | B3: 1 | C3: ZIF-7 | D3: 1.44353 | E3: 3.12929 | F3: 4.34999 | G3: 3930.34 | H3: 0.444385 | I3: 0.307846 | J3: 0.174089 | K3: 1 | N3: 5 | O3: 1 | P3: =MATCH(Q3,$C$3:$C$25,) -> 11 | Q3: UiO-67-F2 | R3: 0.86177 | S3: 6.64219 | T3: 12.83075 | U3: 3058.54 | V3: 0.72311 | W3: 0.839102 | X3: 1 | Y3: 1.428156 | Z3: 1
A4: 15 | B4: 2 | C4: MIL-101(Cr)-NH2 | D4: 1.86975 | E4: 1.16138 | F4: 2.33487 | G4: 4245.26 | H4: 0.36322 | I4: 0.194262 | J4: 0.167245 | K4: 1 | N4: 9 | O4: 2 | P4: =MATCH(Q4,$C$3:$C$25,) -> 9 | Q4: DUT-67 | R4: 1.02671 | S4: 6.62955 | T4: 14.50667 | U4: 2708.09 | V4: 0.699795 | W4: 0.681588 | X4: 1 | Y4: 1.421165 | Z4: 1
A5: 12 | B5: 3 | C5: MIL-96(Al) | D5: 1.15105 | E5: 3.62904 | F5: 8.33017 | G5: 3579.42 | H5: 0.559655 | I5: 0.486214 | J5: 0.157188 | K5: 1 | N5: 31 | O5: 3 | P5: =MATCH(Q5,$C$3:$C$25,) -> #N/A | Q5: 2021[Eu][fcu]3[ASR]2 | R5: 0.789282 | S5: 7.21484 | T5: 14.75035 | U5: 3040.2 | V5: 0.7609 | W5: 0.964041 | X5: 1 | Y5: 1.392622 | Z5: 1
A6: 8 | B6: 4 | C6: PCN-1002 | D6: 1.26921 | E6: 2.05535 | F6: 7.4209 | G6: 3526.25 | H6: 0.52374 | I6: 0.41265 | J6: 0.149558 | K6: 1 | N6: 16 | O6: 4 | P6: =MATCH(Q6,$C$3:$C$25,) -> 18 | Q6: MIL-100 (Fe) | R6: 0.75909 | S6: 8.84616 | T6: 27.76155 | U6: 3270.98 | V6: 0.740035 | W6: 0.974893 | X6: 1 | Y6: 1.311893 | Z6: 1
A7: 1 | B7: 5 | C7: UiO-66 | D7: 1.23478 | E7: 3.82175 | F7: 8.70307 | G7: 2920.55 | H7: 0.590055 | I7: 0.477861 | J7: 0.130723 | K7: 1 | N7: 1 | O7: 5 | P7: =MATCH(Q7,$C$3:$C$25,) -> 5 | Q7: UiO-66 | R7: 1.23478 | S7: 3.82175 | T7: 8.70307 | U7: 2920.55 | V7: 0.590055 | W7: 0.477861 | X7: 1 | Y7: 1.271361 | Z7: 1
A8: 23 | B8: 6 | C8: Ce-BTC | D8: 1.28067 | E8: 6.39825 | F8: 6.62027 | G8: 3272.51 | H8: 0.569755 | I8: 0.44489 | J8: 0.112964 | K8: 1 | N8: 4 | O8: 6 | P8: =MATCH(Q8,$C$3:$C$25,) -> 14 | Q8: UiO-67 | R8: 0.72259 | S8: 6.73387 | T8: 12.96894 | U8: 3474.86 | V8: 0.739285 | W8: 1.02311 | X8: 1 | Y8: 1.260892 | Z8: 1
A9: 3 | B9: 7 | C9: UiO-66-F4 | D9: 1.6404 | E9: 1.08214 | F9: 2.71819 | G9: 4812.39 | H9: 0.281035 | I9: 0.171321 | J9: 0.108609 | K9: 1 | N9: 13 | O9: 7 | P9: =MATCH(Q9,$C$3:$C$25,) -> 12 | Q9: MIL-100(Al) | R9: 0.67864 | S9: 8.49713 | T9: 27.80996 | U9: 3593.18 | V9: 0.73762 | W9: 1.08691 | X9: 1 | Y9: 1.233725 | Z9: 1
A10: 11 | B10: 8 | C10: MIL-53(Al)-as | D10: 1.00403 | E10: 5.95247 | F10: 6.51942 | G10: 3990.86 | H10: 0.58939 | I10: 0.587024 | J10: 0.093254 | K10: 1 | N10: 6 | O10: 8 | P10: =MATCH(Q10,$C$3:$C$25,) -> 20 | Q10: MOF-808 | R10: 1.2841 | S10: 10.09089 | T10: 15.63835 | U10: 2178.08 | V10: 0.62626 | W10: 0.487702 | X10: 1 | Y10: 1.120423 | Z10: 1
A11: 9 | B11: 9 | C11: DUT-67 | D11: 1.02671 | E11: 6.62955 | F11: 14.50667 | G11: 2708.09 | H11: 0.699795 | I11: 0.681588 | J11: 0.077175 | K11: 1 | N11: 7 | O11: 9 | P11: =MATCH(Q11,$C$3:$C$25,) -> 19 | Q11: PCN-999 | R11: 0.58974 | S11: 18.48015 | T11: 19.43968 | U11: 3429.84 | V11: 0.792225 | W11: 1.34336 | X11: 1 | Y11: 1.043442 | Z11: 1
A12: 21 | B12: 10 | C12: HKUST-1 | D12: 0.94885 | E12: 5.21063 | F12: 11.11888 | G12: 3706.74 | H12: 0.68734 | I12: 0.72439 | J12: 0.07033 | K12: 1 | N12: 2 | O12: 10 | P12: =MATCH(Q12,$C$3:$C$25,) -> 13 | Q12: UiO-66-NH2 | R12: 2.02273 | S12: 1.27596 | T12: 7.33306 | U12: 2383.43 | V12: 0.41685 | W12: 0.206083 | X12: 1 | Y12: 1.000167 | Z12: 1
A13: 5 | B13: 11 | C13: UiO-67-F2 | D13: 0.86177 | E13: 6.64219 | F13: 12.83075 | G13: 3058.54 | H13: 0.72311 | I13: 0.839102 | J13: 0.046109 | K13: 1 | N13: 21 | O13: 11 | P13: =MATCH(Q13,$C$3:$C$25,) -> 10 | Q13: HKUST-1 | R13: 0.94885 | S13: 5.21063 | T13: 11.11888 | U13: 3706.74 | V13: 0.68734 | W13: 0.72439 | X13: 1 | Y13: 0.999768 | Z13: 1
A14: 13 | B14: 12 | C14: MIL-100(Al) | D14: 0.67864 | E14: 8.49713 | F14: 27.80996 | G14: 3593.18 | H14: 0.73762 | I14: 1.08691 | J14: 0.009711 | K14: 1 | N14: 23 | O14: 12 | P14: =MATCH(Q14,$C$3:$C$25,) -> 6 | Q14: Ce-BTC | R14: 1.28067 | S14: 6.39825 | T14: 6.62027 | U14: 3272.51 | V14: 0.569755 | W14: 0.44489 | X14: 1 | Y14: 0.969245 | Z14: 1
... A25: 19 | B25: 23 | C25: ZIF-8 | D25: 0.9165 | E25: 3.57948 | F25: 11.98309 | G25: 4995.87 | H25: 0.63599 | I25: 0.693935 | J25: -0.000417 | K25: -1 | N25: 22 | O25: 23 | P25: =MATCH(Q25,$C$3:$C$25,) -> 15 | Q25: Mn-BTC | R25: 1.86613 | S25: 0.62125 | T25: 1.49706 | U25: 4111.54 | V25: 0.186605 | W25: 0.099996 | X25: 1 | Y25: -0.637305 | Z25: 0
N26: 3 | O26: 24 | P26: =MATCH(Q26,$C$3:$C$25,) -> 7 | Q26: UiO-66-F4 | R26: 1.6404 | S26: 1.08214 | T26: 2.71819 | U26: 4812.39 | V26: 0.281035 | W26: 0.171321 | X26: 1 | Y26: -0.957489 | Z26: 0
N27: 29 | O27: 25 | P27: =MATCH(Q27,$C$3:$C$25,) -> #N/A | Q27: 2018[Co][flu]3[ASR]1 | R27: 1.35477 | S27: 2.80323 | T27: 4.4469 | U27: 4347.99 | V27: 0.4299 | W27: 0.317323 | X27: 0 | Y27: -0.985341 | Z27: 0
N28: 28 | O28: 26 | P28: =MATCH(Q28,$C$3:$C$25,) -> #N/A | Q28: 2015[Pr][hcb]2[ASR]1 | R28: 1.51409 | S28: 2.32829 | T28: 4.47729 | U28: 4280.67 | V28: 0.4114 | W28: 0.271715 | X28: 0 | Y28: -0.997498 | Z28: 0
N29: 33 | O29: 27 | P29: =MATCH(Q29,$C$3:$C$25,) -> #N/A | Q29: 2015[Zr][ftw]3[ASR]3 | R29: 0.291153 | S29: 10.49686 | T29: 25.25819 | U29: 4624.66 | V29: 0.8722 | W29: 2.99568 | X29: 0 | Y29: -0.999638 | Z29: 0
N30: 35 | O30: 28 | P30: =MATCH(Q30,$C$3:$C$25,) -> #N/A | Q30: 2020[Fe][hcb]2[ASR]2 | R30: 0.175207 | S30: 15.58313 | T30: 22.94791 | U30: 4287.68 | V30: 0.9308 | W30: 5.31257 | X30: 0 | Y30: -0.999701 | Z30: 0
N31: 26 | O31: 29 | P31: =MATCH(Q31,$C$3:$C$25,) -> #N/A | Q31: 2022[Co][gra]3[ASR]1 | R31: 1.29727 | S31: 2.17637 | T31: 5.07114 | U31: 4526.67 | V31: 0.4473 | W31: 0.3448 | X31: 0 | Y31: -1.000142 | Z31: 0
N32: 34 | O32: 30 | P32: =MATCH(Q32,$C$3:$C$25,) -> #N/A | Q32: 2016[Mg][stp]3[ASR]2 | R32: 0.284192 | S32: 26.5894 | T32: 28.05599 | U32: 4801.7 | V32: 0.8755 | W32: 3.08066 | X32: 0 | Y32: -1.000142 | Z32: 0
N33: 25 | O33: 31 | P33: =MATCH(Q33,$C$3:$C$25,) -> #N/A | Q33: 2008[Co][sql]2[ASR]1 | R33: 1.5197 | S33: 2.42717 | T33: 4.78145 | U33: 4256.24 | V33: 0.3961 | W33: 0.260643 | X33: 0 | Y33: -1.00031 | Z33: 0
N34: 30 | O34: 32 | P34: =MATCH(Q34,$C$3:$C$25,) -> #N/A | Q34: 2023[Zn][nan]3[ASR]12 | R34: 1.49396 | S34: 3.25741 | T34: 4.90141 | U34: 4405.24 | V34: 0.4139 | W34: 0.277049 | X34: 0 | Y34: -1.031774 | Z34: 0
N35: 15 | O35: 33 | P35: =MATCH(Q35,$C$3:$C$25,) -> 2 | Q35: MIL-101(Cr)-NH2 | R35: 1.86975 | S35: 1.16138 | T35: 2.33487 | U35: 4245.26 | V35: 0.36322 | W35: 0.194262 | X35: 1 | Y35: -1.050868 | Z35: 0
N36: 27 | O36: 34 | P36: =MATCH(Q36,$C$3:$C$25,) -> #N/A | Q36: 2024[Cu][pcu]3[ASR]2 | R36: 1.42371 | S36: 2.33203 | T36: 4.03129 | U36: 4418.23 | V36: 0.4097 | W36: 0.287768 | X36: 0 | Y36: -1.075044 | Z36: 0
N37: 24 | O37: 35 | P37: =MATCH(Q37,$C$3:$C$25,) -> #N/A | Q37: 2023[Zn][nan]3[ASR]13 | R37: 1.51073 | S37: 2.30931 | T37: 4.46718 | U37: 4462.1 | V37: 0.4088 | W37: 0.270597 | X37: 0 | Y37: -1.085573 | Z37: 0
B42: Serial | C42: Name | D42: Density | E42: PLD | F42: LCD | G42: GSA | H42: Void_Fraction | I42: Pore_Volume | J42: EnergyScore | K42: svr_score
B43: 1 | C43: 2022[Zr][lvt]3[ASR]1 | D43: 1.07 | E43: 6.93 | F43: 9.83 | G43: 2836.58 | H43: 0.67 | I43: 0.63 | J43: 0.379936 | K43: 0.398546
B44: 2 | C44: 2020[Zn][nan]3[ASR]16 | D44: 1.21 | E44: 11.01 | F44: 11.72 | G44: 2699.02 | H44: 0.67 | I44: 0.55 | J44: 0.347601 | K44: 0.443871
B45: 3 | C45: 2023[La][pts]3[ASR]1 | D45: 1.21 | E45: 7.5 | F45: 8.09 | G45: 3001.63 | H45: 0.62 | I45: 0.51 | J45: 0.551153 | K45: 0.380829
B46: 4 | C46: 2017[Co][nan]3[ASR]5 | D46: 1.38 | E46: 5.76 | F46: 7.7 | G46: 2945.36 | H46: 0.56 | I46: 0.41 | J46: 0.228956 | K46: 0.33216
B47: 5 | C47: 2018[Ce][csq]3[ASR]1 | D47: 0.56 | E47: 17.74 | F47: 23.52 | G47: 3476.89 | H47: 0.81 | I47: 1.44 | J47: 0.332494 | K47: 0.328129
B48: 6 | C48: ic6b02413_si_002_2_FSR_pacman | D48: 0.989594 | E48: 5.93433 | F48: 13.64653 | G48: 2799.06 | H48: 0.70388 | I48: 0.711282 | J48: 0.516035 | K48: 0.428454
B49: 7 | C49: ic6b02413_si_002_2_ASR_pacman | D49: 0.989594 | E49: 5.93433 | F49: 13.64653 | G49: 2799.06 | H49: 0.70388 | I49: 0.711282 | J49: 0.528492 | K49: 0.428454
B50: 8 | C50: ja510525s_si_002_FSR_pacman | D50: 1.08186 | E50: 5.07236 | F50: 12.04251 | G50: 2832.29 | H50: 0.67468 | I50: 0.623629 | J50: 0.743175 | K50: 0.424146
B51: 9 | C51: ja510525s_si_002_ASR_pacman | D51: 1.08186 | E51: 5.07236 | F51: 12.04251 | G51: 2832.29 | H51: 0.67468 | I51: 0.623629 | J51: 0.741055 | K51: 0.424146
B52: 10 | C52: jp8b09178_si_007_FSR_pacman | D52: 0.487583 | E52: 28.06898 | F52: 29.87417 | G52: 3411.27 | H52: 0.8299 | I52: 1.70207 | J52: 0.310761 | K52: 0.410741
B53: 11 | C53: jp8b09178_si_007_ASR_pacman | D53: 0.487583 | E53: 28.06898 | F53: 29.87417 | G53: 3411.27 | H53: 0.8299 | I53: 1.70207 | J53: 0.424331 | K53: 0.410741
B54: 12 | C54: ja8b12530_si_001_3_FSR_pacman | D54: 0.534284 | E54: 29.3367 | F54: 30.79071 | G54: 3455.04 | H54: 0.80936 | I54: 1.51485 | J54: 0.366287 | K54: 0.431288
...

Sheet Sheet2

Sheet coremof_BatchA
F1: =MAX(F3:F1374) -> 0.7190335 | P1: Simulations | U1: Stage 2 - Results
A2: Serial | B2: Name | C2: OCSVM (nu=0.15) | D2: OCSVM+ SVM | E2: SVM (C=1.0) | F2: SVR (C=1.0) | G2: Metal | H2: Topology | I2: Density | J2: PLD | K2: LCD | L2: GSA | M2: Void_Fraction | N2: Pore_Volume | O2: UnitCell_MW_g_mol | P2: Stage 1 recommendation | Q2: Stage 1 Result | R2: Stage 2 - Recom | S2: MetalNum | U2: min (energy) | V2: max (energy) | W2: center of range | X2: goodness coefficient (normalized by the center of the best range)
A3: 328 | B3: 2017[Co][nan]3[ASR]5 | C3: 0.1068212 | D3: =C3*10+E3 -> 2.2835004 | E3: 1.2152885 | F3: 0.33194 | G3: Co | H3: nan | I3: 1.38138 | J3: 5.76311 | K3: 7.69686 | L3: 2945.36 | M3: 0.5597 | N3: 0.405175 | O3: 1103.976 | R3: Recommend | S3: =FIND("]",B3) -> 8 | U3: -8.931 | V3: -8.346 | W3: =U3+(V3-U3)/2 -> -8.6385 | X3: =W3/(-37.73) -> 0.22895574
A4: 707 | B4: 2019[Ni][nan]3[ASR]2 | C4: 0.12904324 | D4: =C4*10+E4 -> 2.2713799 | E4: 0.98094754 | F4: 0.33106139 | G4: Ni | H4: nan | I4: 1.42689 | J4: 3.85272 | K4: 9.29282 | L4: 3157.26 | M4: 0.5376 | N4: 0.376763 | O4: 2241.312 | S4: =FIND("]",B4) -> 8
A5: 190 | B5: 2015[Zr][fcu]3[ASR]1 | C5: 0.098885547 | D5: =C5*10+E5 -> 2.2397029 | E5: 1.2508474 | F5: 0.35678375 | G5: Zr | H5: fcu | I5: 1.22102 | J5: 4.07165 | K5: 8.57883 | L5: 2985.21 | M5: 0.594 | N5: 0.486477 | O5: 1664.064 | S5: =FIND("]",B5) -> 8
A6: 826 | B6: 2020[Co][nan]3[ASR]11 | C6: 0.10381094 | D6: =C6*10+E6 -> 2.1631731 | E6: 1.1250637 | F6: 0.29143166 | G6: Co | H6: nan | I6: 1.39318 | J6: 5.51288 | K6: 6.79448 | L6: 2946.85 | M6: 0.5325 | N6: 0.382219 | O6: 1062.074 | S6: =FIND("]",B6) -> 8
A7: 827 | B7: 2020[Co][nan]3[ASR]12 | C7: 0.10225429 | D7: =C7*10+E7 -> 2.159406 | E7: 1.1368632 | F7: 0.29549135 | G7: Co | H7: nan | I7: 1.37675 | J7: 5.54203 | K7: 6.76639 | L7: 2950.25 | M7: 0.5381 | N7: 0.390847 | O7: 1062.074 | S7: =FIND("]",B7) -> 8
A8: 246 | B8: 2016[Cu][nan]3[ASR]4 | C8: 0.083382933 | D8: =C8*10+E8 -> 2.1587528 | E8: 1.3249234 | F8: 0.39620449 | G8: Cu | H8: nan | I8: 1.39796 | J8: 6.61688 | K8: 9.02855 | L8: 3059.44 | M8: 0.6292 | N8: 0.450085 | O8: 8529.528 | S8: =FIND("]",B8) -> 8
A9: 1009 | B9: 2020[Zr][hex]3[ASR]1 | C9: 0.077750356 | D9: =C9*10+E9 -> 2.149671 | E9: 1.3721674 | F9: 0.38369896 | G9: Zr | H9: hex | I9: 1.10193 | J9: 5.53626 | K9: 8.89938 | L9: 2956.61 | M9: 0.6386 | N9: 0.579527 | O9: 3320.064 | S9: =FIND("]",B9) -> 8
A10: 1215 | B10: 2022[Zr][she]3[ASR]1 | C10: 0.094725733 | D10: =C10*10+E10 -> 2.1496642 | E10: 1.2024069 | F10: 0.36297044 | G10: Zr | H10: she | I10: 0.533204 | J10: 16.86206 | K10: 28.48033 | L10: 3338.07 | M10: 0.8174 | N10: 1.533 | O10: 13546.512 | S10: =FIND("]",B10) -> 8
A11: 247 | B11: 2016[Cu][nan]3[ASR]5 | C11: 0.081801847 | D11: =C11*10+E11 -> 2.1427928 | E11: 1.3247744 | F11: 0.39755707 | G11: Cu | H11: nan | I11: 1.40015 | J11: 6.66192 | K11: 9.05479 | L11: 3068.52 | M11: 0.6314 | N11: 0.450951 | O11: 8529.528 | S11: =FIND("]",B11) -> 8
A12: 1274 | B12: 2023[Sm][pts]3[ASR]1 | C12: 0.085975677 | D12: =C12*10+E12 -> 2.1420473 | E12: 1.2822905 | F12: 0.32622887 | G12: Sm | H12: pts | I12: 1.42856 | J12: 6.2058 | K12: 7.01618 | L12: 2789.87 | M12: 0.5655 | N12: 0.395852 | O12: 592.388 | S12: =FIND("]",B12) -> 8
A13: 245 | B13: 2016[Cu][nan]3[ASR]3 | C13: 0.081435119 | D13: =C13*10+E13 -> 2.0776094 | E13: 1.2632582 | F13: 0.36881874 | G13: Cu | H13: nan | I13: 1.47307 | J13: 6.46579 | K13: 7.90968 | L13: 3048.2 | M13: 0.6068 | N13: 0.411928 | O13: 8529.528 | S13: =FIND("]",B13) -> 8
A14: 1016 | B14: 2020[Zr][sql]2[ASR]1 | C14: 0.090286862 | D14: =C14*10+E14 -> 2.0681924 | E14: 1.1653238 | F14: 0.3939236 | G14: Zr | H14: sql | I14: 1.07971 | J14: 6.2937 | K14: 9.09416 | L14: 3317.4 | M14: 0.6271 | N14: 0.580802 | O14: 3490.41 | S14: =FIND("]",B14) -> 8
A15: 1255 | B15: 2023[La][pts]3[ASR]1 | C15: 0.072164796 | D15: =C15*10+E15 -> 2.0488329 | E15: 1.3271849 | F15: 0.38093532 | G15: La | H15: pts | I15: 1.21149 | J15: 7.50315 | K15: 8.08695 | L15: 3001.63 | M15: 0.6208 | N15: 0.512427 | O15: 870.198 | R15: Recommend | S15: =FIND("]",B15) -> 8 | U15: -21.3 | V15: -20.29 | W15: =U15+(V15-U15)/2 -> -20.795 | X15: =W15/(-37.73) -> 0.55115293
A16: 154 | B16: 2015[Eu][nan]3[ASR]2 | C16: 0.11312711 | D16: =C16*10+E16 -> 2.040285 | E16: 0.90901383 | F16: 0.29494735 | G16: Eu | H16: nan | I16: 1.4765 | J16: 5.75162 | K16: 7.46222 | L16: 3184.96 | M16: 0.521 | N16: 0.352862 | O16: 1436.556 | S16: =FIND("]",B16) -> 8
A17: 269 | B17: 2016[Zn][fgl]3[ASR]1 | C17: 0.067549754 | D17: =C17*10+E17 -> 2.0378445 | E17: 1.362347 | F17: 0.41036656 | G17: Zn | H17: fgl | I17: 1.33966 | J17: 8.63635 | K17: 9.32756 | L17: 2951.3 | M17: 0.6255 | N17: 0.466909 | O17: 1949.148 | S17: =FIND("]",B17) -> 8
A18: 281 | B18: 2017[Ag][sqc]3[ASR]1 | C18: 0.063647239 | D18: =C18*10+E18 -> 2.0299102 | E18: 1.3934378 | F18: 0.41795172 | G18: Ag | H18: sqc | I18: 1.14094 | J18: 8.15582 | K18: 10.30618 | L18: 3098.2 | M18: 0.6714 | N18: 0.58846 | O18: 2017.8 | S18: =FIND("]",B18) -> 8
A19: 910 | B19: 2020[InTb][nan]3[ASR]1 | C19: 0.096683803 | D19: =C19*10+E19 -> 2.0284939 | E19: 1.0616559 | F19: 0.38434472 | G19: InTb | H19: nan | I19: 1.14162 | J19: 6.29302 | K19: 8.80596 | L19: 3370.99 | M19: 0.6087 | N19: 0.533189 | O19: 3130.976 | S19: =FIND("]",B19) -> 10
A20: 727 | B20: 2019[V][bpq]3[ASR]4 | C20: 0.096419587 | D20: =C20*10+E20 -> 2.0202057 | E20: 1.0560098 | F20: 0.31173574 | G20: V | H20: bpq | I20: 1.39001 | J20: 5.55808 | K20: 6.75373 | L20: 3132.25 | M20: 0.5612 | N20: 0.403737 | O20: 1239.812 | S20: =FIND("]",B20) -> 7
A21: 825 | B21: 2020[Co][nan]3[ASR]10 | C21: 0.1013791 | D21: =C21*10+E21 -> 2.0173448 | E21: 1.0035537 | F21: 0.24462644 | G21: Co | H21: nan | I21: 1.48421 | J21: 4.87145 | K21: 6.08066 | L21: 2962.37 | M21: 0.5027 | N21: 0.3387 | O21: 1062.074 | S21: =FIND("]",B21) -> 8
A22: 1191 | B22: 2022[Tb][nan]3[ASR]1 | C22: 0.086942881 | D22: =C22*10+E22 -> 2.0079218 | E22: 1.138493 | F22: 0.49139676 | G22: Tb | H22: nan | I22: 1.07791 | J22: 4.57498 | K22: 16.5065 | L22: 3494.27 | M22: 0.6423 | N22: 0.595878 | O22: 6902.478 | S22: =FIND("]",B22) -> 8
A23: 1214 | B23: 2022[Zr][lvt]3[ASR]1 | C23: 0.056268905 | D23: =C23*10+E23 -> 1.999099 | E23: 1.43641 | F23: 0.39806795 | G23: Zr | H23: lvt | I23: 1.0669 | J23: 6.93493 | K23: 9.83426 | L23: 2836.58 | M23: 0.6733 | N23: 0.631079 | O23: 5783.264 | R23: Recommend | S23: =FIND("]",B23) -> 8 | U23: -14.74 | V23: -13.93 | W23: =U23+(V23-U23)/2 -> -14.335 | X23: =W23/(-37.73) -> 0.37993639
A24: 325 | B24: 2017[Co][nan]3[ASR]2 | C24: 0.099985949 | D24: =C24*10+E24 -> 1.9939847 | E24: 0.99412526 | F24: 0.23700717 | G24: Co | H24: nan | I24: 1.51985 | J24: 4.766 | K24: 5.99534 | L24: 2947.57 | M24: 0.4968 | N24: 0.326873 | O24: 1066.106 | S24: =FIND("]",B24) -> 8
A25: 774 | B25: 2019[Zr][bcu]3[ASR]2 | C25: 0.05637206 | D25: =C25*10+E25 -> 1.9886496 | E25: 1.424929 | F25: 0.41916155 | G25: Zr | H25: bcu | I25: 0.952429 | J25: 8.95756 | K25: 11.33088 | L25: 3021.69 | M25: 0.685 | N25: 0.719214 | O25: 1532.04 | S25: =FIND("]",B25) -> 8
A26: 1018 | B26: 2021[Ag][nan]3[ASR]1 | C26: 0.068668003 | D26: =C26*10+E26 -> 1.9874152 | E26: 1.3007351 | F26: 0.42146508 | G26: Ag | H26: nan | I26: 1.38549 | J26: 8.74983 | K26: 9.77195 | L26: 3114.85 | M26: 0.6202 | N26: 0.44764 | O26: 1185.56 | S26: =FIND("]",B26) -> 8
A27: 621 | B27: 2019[Cu][gar]3[ASR]1 | C27: 0.089872901 | D27: =C27*10+E27 -> 1.9864367 | E27: 1.0877077 | F27: 0.37627042 | G27: Cu | H27: gar | I27: 1.25702 | J27: 5.79853 | K27: 8.37218 | L27: 3322.48 | M27: 0.6137 | N27: 0.488216 | O27: 11575.32 | S27: =FIND("]",B27) -> 8
A28: 280 | B28: 2017[Ag][sqc]2[ASR]1 | C28: 0.060389542 | D28: =C28*10+E28 -> 1.9849288 | E28: 1.3810334 | F28: 0.43102617 | G28: Ag | H28: sqc | I28: 1.11653 | J28: 9.25829 | K28: 10.88694 | L28: 3121.04 | M28: 0.6651 | N28: 0.595683 | O28: 1008.9 | S28: =FIND("]",B28) -> 8
A29: 672 | B29: 2019[In][bpq]3[ASR]2 | C29: 0.078954467 | D29: =C29*10+E29 -> 1.9793232 | E29: 1.1897785 | F29: 0.3324548 | G29: In | H29: bpq | I29: 1.41086 | J29: 6.08989 | K29: 6.68867 | L29: 3045.09 | M29: 0.5864 | N29: 0.415632 | O29: 2615.448 | S29: =FIND("]",B29) -> 8
A30: 1303 | B30: 2024[CeCu][nan]3[ASR]1 | C30: 0.079908537 | D30: =C30*10+E30 -> 1.9746144 | E30: 1.175529 | F30: 0.26319383 | G30: CeCu | H30: nan | I30: 1.75597 | J30: 4.93687 | K30: 6.13228 | L30: 2702.62 | M30: 0.5135 | N30: 0.29243 | O30: 857.154 | S30: =FIND("]",B30) -> 10
A31: 947 | B31: 2020[Tb][nan]3[ASR]2 | C31: 0.085433634 | D31: =C31*10+E31 -> 1.9742839 | E31: 1.1199476 | F31: 0.34694149 | G31: Tb | H31: nan | I31: 1.27052 | J31: 6.29629 | K31: 7.19811 | L31: 3188.06 | M31: 0.5911 | N31: 0.465242 | O31: 2910.846 | S31: =FIND("]",B31) -> 8
A32: 897 | B32: 2020[Fe][hcb]2[ASR]1 | C32: 0.090624472 | D32: =C32*10+E32 -> 1.9615539 | E32: 1.0553092 | F32: 0.36486031 | G32: Fe | H32: hcb | I32: 1.26567 | J32: 6.59237 | K32: 7.94542 | L32: 3301.94 | M32: 0.593 | N32: 0.468528 | O32: 3922.132 | S32: =FIND("]",B32) -> 8
A33: 1288 | B33: 2023[Zn][nan]3[ASR]17 | C33: 0.094287935 | D33: =C33*10+E33 -> 1.9511532 | E33: 1.0082738 | F33: 0.28556799 | G33: Zn | H33: nan | I33: 1.85614 | J33: 6.36678 | K33: 7.38612 | L33: 3005.45 | M33: 0.5005 | N33: 0.269646 | O33: 2132.352 | S33: =FIND("]",B33) -> 8
A34: 1334 | B34: 2024[Tb][sql]2[ASR]2 | C34: 0.10082589 | D34: =C34*10+E34 -> 1.9327672 | E34: 0.92450821 | F34: 0.29882097 | G34: Tb | H34: sql | I34: 1.54132 | J34: 5.68466 | K34: 6.89087 | L34: 3210.5 | M34: 0.5409 | N34: 0.350932 | O34: 1628.374 | S34: =FIND("]",B34) -> 8
A35: 1081 | B35: 2021[Eu][nan]3[ASR]2 | C35: 0.083740269 | D35: =C35*10+E35 -> 1.931992 | E35: 1.0945893 | F35: 0.35085831 | G35: Eu | H35: nan | I35: 1.43096 | J35: 7.74888 | K35: 7.87258 | L35: 3128.51 | M35: 0.5524 | N35: 0.386035 | O35: 3273.32 | S35: =FIND("]",B35) -> 8
... A51: 250 | B51: 2016[Ga][nan]3[ASR]1 | C51: 0.079016667 | D51: =C51*10+E51 -> 1.8904089 | E51: 1.1002422 | F51: 0.35071194 | G51: Ga | H51: nan | I51: 1.21033 | J51: 7.04653 | K51: 7.15937 | L51: 3216.11 | M51: 0.5872 | N51: 0.485156 | O51: 1440.92 | S51: =FIND("]",B51) -> 8
A52: 478 | B52: 2018[Ce][csq]3[ASR]1 | C52: 0.078899562 | D52: =C52*10+E52 -> 1.8878765 | E52: 1.0988809 | F52: 0.33038622 | G52: Ce | H52: csq | I52: 0.557854 | J52: 17.73807 | K52: 23.51979 | L52: 3476.89 | M52: 0.8053 | N52: 1.44357 | O52: 5452.68 | R52: Recommend | S52: =FIND("]",B52) -> 8 | U52: -12.64 | V52: -12.45 | W52: =U52+(V52-U52)/2 -> -12.545 | X52: =W52/(-37.73) -> 0.33249404
A53: 14 | B53: 0000[Cu][tbo]3[ASR]2 | C53: 0.051797266 | D53: =C53*10+E53 -> 1.8850913 | E53: 1.3671186 | F53: 0.41564142 | G53: Cu | H53: tbo | I53: 0.888494 | J53: 6.65523 | K53: 13.20142 | L53: 3310.85 | M53: 0.7192 | N53: 0.80946 | O53: 9677.952 | S53: =FIND("]",B53) -> 8
A54: 971 | B54: 2020[Zn][nan]2[ASR]2 | C54: 0.059934557 | D54: =C54*10+E54 -> 1.8843575 | E54: 1.2850119 | F54: 0.36125431 | G54: Zn | H54: nan | I54: 1.409 | J54: 6.28404 | K54: 7.16487 | L54: 3033.29 | M54: 0.6263 | N54: 0.4445 | O54: 1200.26 | S54: =FIND("]",B54) -> 8
A55: 885 | B55: 2020[Cu][tbo]3[ASR]4 | C55: 0.053058731 | D55: =C55*10+E55 -> 1.884207 | E55: 1.3536197 | F55: 0.41628538 | G55: Cu | H55: tbo | I55: 0.881994 | J55: 6.70666 | K55: 13.18109 | L55: 3342.28 | M55: 0.7176 | N55: 0.813611 | O55: 2419.488 | S55: =FIND("]",B55) -> 8
...

Sheet FSR_BatchB
E1: =MAX(E3:E1194) -> 0.71961531
A2: Serial | B2: name | C2: OCSVM (nu=0.15) | D2: SVM(C=1.0) | E2: SVR(C=1.0) | F2: Metal | G2: Topology | H2: Density | I2: PLD | J2: LCD | K2: GSA | L2: Void_Fraction | M2: Pore_Volume | N2: UnitCell_MW_g_mol | Q2: min (energy) | R2: max (energy) | S2: center of range | T2: goodness coefficient (normalized by the center of the best range)
A3: 1 | B3: 2004[Cu][mog]3[FSR]2 | C3: 0.14797289 | D3: -0.98091948 | E3: 0.12902029 | F3: Cu | G3: mog | H3: 1.38697 | I3: 2.64467 | J3: 4.89477 | K3: 4487.13 | L3: 0.45116 | M3: 0.325285 | N3: 5687.616 | P3: =FIND("]",B3) -> 8
A4: 2 | B4: 2006[V][rna]3[FSR]1 | C4: 0.089515366 | D4: 0.54315749 | E4: 0.22897686 | F4: V | G4: rna | H4: 1.46805 | I4: 2.79583 | J4: 5.42081 | K4: 3393.95 | L4: 0.53374 | M4: 0.36357 | N4: 1695.58 | P4: =FIND("]",B4) -> 7
A5: 3 | B5: 2007[CuEu][nan]3[FSR]1 | C5: 0.061071828 | D5: 0.3090911 | E5: 0.084143264 | F5: CuEu | G5: nan | H5: 2.03259 | I5: 3.85822 | J5: 4.40951 | K5: 3183.68 | L5: 0.36164 | M5: 0.177921 | N5: 1943.82 | P5: =FIND("]",B5) -> 10
A6: 4 | B6: 2007[In][ctn]3[FSR]1 | C6: -0.030416424 | D6: 1.1394559 | E6: 0.35950587 | F6: In | G6: ctn | H6: 0.921299 | I6: 5.48176 | J6: 6.56544 | K6: 3400.11 | L6: 0.7015 | M6: 0.761425 | N6: 4691.688 | P6: =FIND("]",B6) -> 8
A7: 5 | B7: 2007[Zn][nan]3[FSR]1 | C7: 0.088121794 | D7: -0.26766846 | E7: 0.21974827 | F7: Zn | G7: nan | H7: 1.26993 | I7: 2.40607 | J7: 4.69949 | K7: 4035.17 | L7: 0.54868 | M7: 0.432056 | N7: 3848.432 | P7: =FIND("]",B7) -> 8
A8: 6 | B8: 2007[Zn][nan]3[FSR]2 | C8: 0.086980655 | D8: -0.23908328 | E8: 0.24321958 | F8: Zn | G8: nan | H8: 1.2255 | I8: 3.08135 | J8: 4.95649 | K8: 4100.56 | L8: 0.56162 | M8: 0.458277 | N8: 3848.432 | P8: =FIND("]",B8) -> 8
A9: 7 | B9: 2007[Zn][pcu]3[FSR]3 | C9: -0.099891875 | D9: 1.0599132 | E9: 0.31883304 | F9: Zn | G9: pcu | H9: 0.595037 | I9: 8.20898 | J9: 15.04033 | K9: 3622.94 | L9: 0.81102 | M9: 1.36298 | N9: 1539.734 | P9: =FIND("]",B9) -> 8
A10: 8 | B10: 2007[Zn][srs]3[FSR]10 | C10: 0.053478556 | D10: 1.2442008 | E10: 0.39574917 | F10: Zn | G10: srs | H10: 1.23149 | I10: 6.75539 | J10: 8.59914 | K10: 3285.95 | L10: 0.66224 | M10: 0.537756 | N10: 12657.888 | P10: =FIND("]",B10) -> 8
A11: 9 | B11: 2007[Zn][srs]3[FSR]11 | C11: 0.05079937 | D11: 1.2580806 | E11: 0.39582488 | F11: Zn | G11: srs | H11: 1.23146 | I11: 6.77259 | J11: 8.60968 | K11: 3273.44 | L11: 0.66574 | M11: 0.540609 | N11: 12657.888 | P11: =FIND("]",B11) -> 8
A12: 10 | B12: 2007[Zn][srs]3[FSR]12 | C12: 0.048190908 | D12: 1.2594532 | E12: 0.39803868 | F12: Zn | G12: srs | H12: 1.22695 | I12: 7.15145 | J12: 8.64577 | K12: 3281.53 | L12: 0.6664 | M12: 0.543135 | N12: 12657.888 | P12: =FIND("]",B12) -> 8
A13: 11 | B13: 2007[Zn][srs]3[FSR]13 | C13: 0.046688322 | D13: 1.2470186 | E13: 0.39439555 | F13: Zn | G13: srs | H13: 1.21042 | I13: 6.8958 | J13: 8.47518 | K13: 3292.62 | L13: 0.66746 | M13: 0.551427 | N13: 12657.888 | P13: =FIND("]",B13) -> 8
A14: 12 | B14: 2007[Zn][srs]3[FSR]14 | C14: 0.047977875 | D14: 1.2603077 | E14: 0.39856279 | F14: Zn | G14: srs | H14: 1.20596 | I14: 7.09618 | J14: 8.73075 | K14: 3290.39 | L14: 0.66912 | M14: 0.554843 | N14: 12657.888 | P14: =FIND("]",B14) -> 8
... A222: 220 | B222: 2016[Sm][kgd]2[FSR]1 | C222: 0.11528423 | D222: -0.21805712 | E222: 0.14587649 | F222: Sm | G222: kgd | H222: 1.52805 | I222: 3.55732 | J222: 4.53816 | K222: 3771.48 | L222: 0.473 | M222: 0.309545 | N222: 754.578 | P222: =FIND("]",B222) -> 8
A223: 221 | B223: 2016[Tb][fcu]3[FSR]1 | C223: 0.0094821042 | D223: 1.4058074 | E223: 0.3878289 | F223: Tb | G223: fcu | H223: 0.804274 | I223: 6.94679 | J223: 13.37735 | K223: 3091.16 | L223: 0.74496 | M223: 0.926251 | N223: 2530.89 | P223: =FIND("]",B223) -> 8 | Q223: -10.81 | R223: -10.73 | S223: =Q223-(R223-Q223)/2 -> -10.85 | T223: =S223/(-37.73) -> 0.28756957
A224: 222 | B224: 2016[Ti][srs]3[FSR]1 | C224: -0.11213534 | D224: 0.86630557 | E224: 0.35580167 | F224: Ti | G224: srs | H224: 0.748874 | I224: 4.43359 | J224: 6.24453 | K224: 3742.73 | L224: 0.72982 | M224: 0.974556 | N224: 4658.352 | P224: =FIND("]",B224) -> 8
A225: 224 | B225: 2016[Zn][dia]3[FSR]1 | C225: 0.090115031 | D225: -0.58183391 | E225: 0.24437014 | F225: Zn | G225: dia | H225: 1.13028 | I225: 4.26969 | J225: 5.60587 | K225: 4768.61 | L225: 0.5414 | M225: 0.478997 | N225: 3533.696 | P225: =FIND("]",B225) -> 8
A226: 225 | B226: 2016[Zn][fgl]3[FSR]1 | C226: 0.066707998 | D226: 1.3671479 | E226: 0.41025261 | F226: Zn | G226: fgl | H226: 1.33966 | I226: 8.63635 | J226: 9.32756 | K226: 2939.71 | L226: 0.62718 | M226: 0.468163 | N226: 1949.148 | P226: =FIND("]",B226) -> 8
A227: 226 | B227: 2016[Zn][kgd]2[FSR]1 | C227: 0.12153007 | D227: -0.73466428 | E227: 0.20094685 | F227: Zn | G227: kgd | H227: 1.18629 | I227: 2.68384 | J227: 5.23122 | K227: 4558.66 | L227: 0.51864 | M227: 0.437193 | N227: 2709.18 | P227: =FIND("]",B227) -> 8
A228: 227 | B228: 2016[Zn][nan]2[FSR]1 | C228: 0.14702516 | D228: -1.1197135 | E228: 0.070478173 | F228: Zn | G228: nan | H228: 1.55981 | I228: 2.28398 | J228: 3.76708 | K228: 4473.14 | L228: 0.39266 | M228: 0.251735 | N228: 1398.524 | P228: =FIND("]",B228) -> 8 | Q228: n/a | R228: n/a
A229: 228 | B229: 2016[Zn][nan]2[FSR]2 | C229: 0.1419564 | D229: -1.086822 | E229: 0.068419623 | F229: Zn | G229: nan | H229: 1.62126 | I229: 3.12435 | J229: 3.98891 | K229: 4378.28 | L229: 0.3824 | M229: 0.235866 | N229: 5169.58 | P229: =FIND("]",B229) -> 8
A230: 229 | B230: 2016[Zn][nan]3[FSR]12 | C230: 0.091855492 | D230: -0.59844087 | E230: 0.24266099 | F230: Zn | G230: nan | H230: 1.10689 | I230: 4.56374 | J230: 6.15612 | K230: 4834.01 | L230: 0.52758 | M230: 0.476635 | N230: 2778.676 | P230: =FIND("]",B230) -> 8
A231: 230 | B231: 2016[Zn][nan]3[FSR]13 | C231: 0.042236238 | D231: 0.85200187 | E231: 0.41813654 | F231: Zn | G231: nan | H231: 0.908716 | I231: 5.03657 | J231: 12.11623 | K231: 3930.35 | L231: 0.69672 | M231: 0.766708 | N231: 9702.528 | P231: =FIND("]",B231) -> 8
A232: 231 | B232: 2016[Zn][nan]3[FSR]5 | C232: 0.021316548 | D232: -0.23522085 | E232: 0.3095128 | F232: Zn | G232: nan | H232: 0.951977 | I232: 5.57065 | J232: 6.92787 | K232: 4963.67 | L232: 0.58936 | M232: 0.61909 | N232: 3758.448 | P232: =FIND("]",B232) -> 8
A233: 232 | B233: 2016[Zn][sql]2[FSR]1 | C233: 0.091610702 | D233: -0.78070225 | E233: 0.18067267 | F233: Zn | G233: sql | H233: 1.24339 | I233: 3.29167 | J233: 4.96746 | K233: 5084.99 | L233: 0.45204 | M233: 0.363553 | N233: 5023.696 | P233: =FIND("]",B233) -> 8
A234: 223 | B234: 2016[ZnCo][pcu]3[FSR]1 | C234: -0.056311268 | D234: 1.2049869 | E234: 0.33149149 | F234: ZnCo | G234: pcu | H234: 0.64452 | I234: 11.01743 | J234: 13.54262 | K234: 3401.69 | L234: 0.7845 | M234: 1.21719 | N234: 7312.148 | P234: =FIND("]",B234) -> 10
A235: 233 | B235: 2016[Zr][buh]3[FSR]1 | C235: -0.34261977 | D235: 0.055134156 | E235: 0.34875098 | F235: Zr | G235: buh | H235: 0.389439 | I235: 10.77877 | J235: 18.84439 | K235: 4186.97 | L235: 0.8383 | M235: 2.15259 | N235: 27325.632 | P235: =FIND("]",B235) -> 8
A236: 234 | B236: 2017[Ag][dia]3[FSR]1 | C236: 0.13568607 | D236: -0.8182579 | E236: 0.14315294 | F236: Ag | G236: dia | H236: 1.37041 | I236: 3.54801 | J236: 4.58322 | K236: 4300.22 | L236: 0.46848 | M236: 0.341854 | N236: 4677.496 | P236: =FIND("]",B236) -> 8
A237: 235 | B237: 2017[Ag][sqc]2[FSR]1 | C237: 0.056802194 | D237: 1.1879529 | E237: 0.38908405 | F237: Ag | G237: sqc | H237: 1.15952 | I237: 7.16012 | J237: 8.14975 | K237: 3319.88 | L237: 0.64632 | M237: 0.557405 | N237: 1080.96 | P237: =FIND("]",B237) -> 8
A238: 236 | B238: 2017[Ag][sqc]3[FSR]1 | C238: 0.070745728 | D238: 1.385225 | E238: 0.42009389 | F238: Ag | G238: sqc | H238: 1.14094 | I238: 8.15582 | J238: 10.30618 | K238: 3098.69 | L238: 0.66166 | M238: 0.579924 | N238: 2017.8 | P238: =FIND("]",B238) -> 8
A239: 237 | B239: 2017[Al][fon]3[FSR]1 | C239: -0.15861246 | D239: 0.51349219 | E239: 0.38165782 | F239: Al | G239: fon | H239: 0.593343 | I239: 8.07582 | J239: 10.22463 | K239: 4442.44 | L239: 0.73968 | M239: 1.24663 | N239: 4115.536 | P239: =FIND("]",B239) -> 8
A240: 238 | B240: 2017[Al][skl]3[FSR]1 | C240: -0.10190157 | D240: 0.45834025 | E240: 0.38923008 | F240: Al | G240: skl | H240: 0.633677 | I240: 6.4126 | J240: 10.57915 | K240: 4501.62 | L240: 0.71722 | M240: 1.13184 | N240: 4716.256 | P240: =FIND("]",B240) -> 8
... A339: 338 | B339: 2017[Ni][dia]3[FSR]3 | C339: 0.12844234 | D339: -0.76774004 | E339: 0.18334754 | F339: Ni | G339: dia | H339: 1.25034 | I339: 3.51885 | J339: 4.97777 | K339: 4454.82 | L339: 0.49996 | M339: 0.399859 | N339: 605.798 | P339: =FIND("]",B339) -> 8
A340: 339 | B340: 2017[Ni][hms]3[FSR]1 | C340: 0.1413979 | D340: -1.1367094 | E340: 0.056215165 | F340: Ni | G340: hms | H340: 1.52424 | I340: 2.34169 | J340: 3.06322 | K340: 4474.05 | L340: 0.37466 | M340: 0.245802 | N340: 2531.988 | P340: =FIND("]",B340) -> 8 | Q340: n/a | R340: n/a
A341: 340 | B341: 2017[Ni][nan]3[FSR]1 | C341: 0.097697502 | D341: -0.19906419 | E341: 0.33442927 | F341: Ni | G341: nan | H341: 1.02982 | I341: 3.37663 | J341: 10.60685 | K341: 4605.17 | L341: 0.57982 | M341: 0.563029 | N341: 19488.168 | P341: =FIND("]",B341) -> 8
A342: 341 | B342: 2017[Ni][nan]3[FSR]4 | C342: -0.031952052 | D342: 0.087557989 | E342: 0.36116231 | F342: Ni | G342: nan | H342: 0.754862 | I342: 4.5461 | J342: 8.68471 | K342: 4840.17 | L342: 0.65748 | M342: 0.870994 | N342: 1374.778 | P342: =FIND("]",B342) -> 8
A343: 342 | B343: 2017[Ni][sqc]3[FSR]1 | C343: 0.13729755 | D343: -0.96262711 | E343: 0.1504444 | F343: Ni | G343: sqc | H343: 1.24976 | I343: 3.3599 | J343: 4.99445 | K343: 4701.54 | L343: 0.45348 | M343: 0.362853 | N343: 4513.432 | P343: =FIND("]",B343) -> 8
A344: 343 | B344: 2017[Ni][sql]2[FSR]1 | C344: 0.09632486 | D344: -0.44396133 | E344: 0.25800202 | F344: Ni | G344: sql | H344: 1.06415 | I344: 4.65274 | J344: 5.75291 | K344: 4453.46 | L344: 0.55246 | M344: 0.519155 | N344: 1296.338 | P344: =FIND("]",B344) -> 8
A345: 344 | B345: 2017[Ni][sql]2[FSR]2 | C345: 0.11944831 | D345: -0.71340979 | E345: 0.19341203 | F345: Ni | G345: sql | H345: 1.17221 | I345: 3.33074 | J345: 4.70193 | K345: 4450.78 | L345: 0.51474 | M345: 0.439119 | N345: 1246.278 | P345: =FIND("]",B345) -> 8
...

Sheet Ion_BatchB
E1: =MAX(E3:E102) -> 0.46323641
A2: Serial | B2: name | C2: OCSVM (nu=0.15) | D2: SVM(C=1.0) | E2: SVR(C=1.0) | F2: Metal | G2: Topology | H2: Density | I2: PLD | J2: LCD | K2: GSA | L2: Void_Fraction | M2: Pore_Volume | N2: UnitCell_MW_g_mol | Q2: min (energy) | R2: max (energy) | S2: center of range | T2: goodness coefficient (normalized by the center of the best range)
A3: 41 | B3: 2018[ZnMo][qtz]3[ION]2 | C3: 0.042229035 | D3: 1.1813023 | E3: 0.25658774 | F3: =MID(B3,6,P3-6) -> ZnMo | G3: qtz | H3: 2.07929 | I3: 3.78303 | J3: 6.0504 | K3: 2445.48 | L3: 0.50178 | M3: 0.241323 | N3: 3986.976 | P3: =FIND("]",B3) -> 10 | Q3: -10.65 | R3: -9.882 | S3: =Q3+(R3-Q3)/2 -> -10.266 | T3: =S3/(-37.73) -> 0.27209117
A4: 40 | B4: 2018[ZnMo][qtz]3[ION]1 | C4: 0.042229035 | D4: 1.1813023 | E4: 0.25658774 | F4: =MID(B4,6,P4-6) -> ZnMo | G4: qtz | H4: 2.07929 | I4: 3.78303 | J4: 6.0504 | K4: 2445.48 | L4: 0.50178 | M4: 0.241323 | N4: 3986.976 | P4: =FIND("]",B4) -> 10 | Q4: -6.637 | R4: -5.154 | S4: =Q4+(R4-Q4)/2 -> -5.8955 | T4: =S4/(-37.73) -> 0.15625497
A5: 65 | B5: 2019[Tb][she]3[ION]1 | C5: -0.017697735 | D5: 1.0148608 | E5: 0.34554432 | F5: =MID(B5,6,P5-6) -> Tb | G5: she | H5: 0.595012 | I5: 8.51123 | J5: 20.86689 | K5: 3810.29 | L5: 0.79738 | M5: 1.34011 | N5: 14806.32 | P5: =FIND("]",B5) -> 8
A6: 79 | B6: 2020[UEu][nan]3[ION]1 | C6: 0.0095894173 | D6: 0.88693022 | E6: 0.1644739 | F6: =MID(B6,6,P6-6) -> UEu | G6: nan | H6: 2.73059 | I6: 2.44956 | J6: 5.76815 | K6: 2569.7 | L6: 0.38354 | M6: 0.14046 | N6: 2981 | P6: =FIND("]",B6) -> 9
A7: 14 | B7: 2015[Zn][hww]3[ION]4 | C7: -0.068104588 | D7: 0.83554112 | E7: 0.37976823 | F7: =MID(B7,6,P7-6) -> Zn | G7: hww | H7: 0.708452 | I7: 10.97379 | J7: 12.38306 | K7: 4108.57 | L7: 0.74206 | M7: 1.04744 | N7: 4332.72 | P7: =FIND("]",B7) -> 8
A8: 15 | B8: 2015[Zn][hww]3[ION]5 | C8: -0.097513225 | D8: 0.7726714 | E8: 0.37493653 | F8: =MID(B8,6,P8-6) -> Zn | G8: hww | H8: 0.68985 | I8: 11.81293 | J8: 12.33521 | K8: 4173.96 | L8: 0.74628 | M8: 1.0818 | N8: 4384.796 | P8: =FIND("]",B8) -> 8
A9: 11 | B9: 2015[Zn][hww]3[ION]1 | C9: -0.0044156895 | D9: 0.7311959 | E9: 0.39748552 | F9: =MID(B9,6,P9-6) -> Zn | G9: hww | H9: 0.860339 | I9: 8.30648 | J9: 9.45178 | K9: 4054.92 | L9: 0.6893 | M9: 0.801196 | N9: 3888.4 | P9: =FIND("]",B9) -> 8
A10: 24 | B10: 2017[Ag][nan]2[ION]2 | C10: -0.070992782 | D10: 0.73091772 | E10: 0.45973663 | F10: =MID(B10,6,P10-6) -> Ag | G10: nan | H10: 1.07134 | I10: 12.4101 | J10: 15.0451 | K10: 4092.47 | L10: 0.61478 | M10: 0.573842 | N10: 4399.468 | P10: =FIND("]",B10) -> 8
A11: 67 | B11: 2019[YK][nan]3[ION]1 | C11: 0.054961627 | D11: 0.72315107 | E11: 0.1289693 | F11: =MID(B11,6,P11-6) -> YK | G11: nan | H11: 1.66843 | I11: 3.69279 | J11: 4.85328 | K11: 2860.99 | L11: 0.38562 | M11: 0.231128 | N11: 17802.976 | P11: =FIND("]",B11) -> 8
A12: 16 | B12: 2015[Zn][hwx]3[ION]1 | C12: -0.028398453 | D12: 0.66168979 | E12: 0.39228249 | F12: =MID(B12,6,P12-6) -> Zn | G12: hwx | H12: 0.841511 | I12: 8.50309 | J12: 8.98014 | K12: 4147.28 | L12: 0.69634 | M12: 0.827487 | N12: 3796.344 | P12: =FIND("]",B12) -> 8
A13: 13 | B13: 2015[Zn][hww]3[ION]3 | C13: -0.11195572 | D13: 0.65718133 | E13: 0.36963449 | F13: =MID(B13,6,P13-6) -> Zn | G13: hww | H13: 0.722395 | I13: 5.323 | J13: 7.27167 | K13: 4109.5 | L13: 0.74062 | M13: 1.02523 | N13: 4232.6 | P13: =FIND("]",B13) -> 8
A14: 12 | B14: 2015[Zn][hww]3[ION]2 | C14: -0.011093731 | D14: 0.64725146 | E14: 0.39387979 | F14: =MID(B14,6,P14-6) -> Zn | G14: hww | H14: 0.861385 | I14: 8.41653 | J14: 8.93966 | K14: 4111.98 | L14: 0.68134 | M14: 0.790982 | N14: 3988.52 | P14: =FIND("]",B14) -> 8
A15: 23 | B15: 2017[Ag][nan]2[ION]1 | C15: -0.10017479 | D15: 0.62317211 | E15: 0.46323641 | F15: =MID(B15,6,P15-6) -> Ag | G15: nan | H15: 1.16268 | I15: 12.60572 | J15: 15.22274 | K15: 4120.67 | L15: 0.58414 | M15: 0.50241 | N15: 4996.144 | P15: =FIND("]",B15) -> 8
A16: 25 | B16: 2017[Ag][nan]2[ION]3 | C16: -0.09699955 | D16: 0.6006266 | E16: 0.45970282 | F16: =MID(B16,6,P16-6) -> Ag | G16: nan | H16: 1.14369 | I16: 12.49997 | J16: 15.09274 | K16: 4147.83 | L16: 0.58488 | M16: 0.511397 | N16: 4667.788 | P16: =FIND("]",B16) -> 8
... A24: 90 | B24: 2022[CuSi][ith]3[ION]1 | C24: 0.082837013 | D24: 0.091462726 | E24: 0.3738889 | F24: =MID(B24,6,P24-6) -> CuSi | G24: ith | H24: 0.993357 | I24: 2.63507 | J24: 11.42007 | K24: 4324.67 | L24: 0.61038 | M24: 0.614462 | N24: 3051.516 | P24: =FIND("]",B24) -> 10
A25: 20 | B25: 2016[La][sql]2[ION]1 | C25: 0.054703837 | D25: 0.066589646 | E25: 0.040224492 | F25: =MID(B25,6,P25-6) -> La | G25: sql | H25: 2.14744 | I25: 2.63172 | J25: 3.24922 | K25: 3303.47 | L25: 0.3395 | M25: 0.158095 | N25: 1014.836 | P25: =FIND("]",B25) -> 8 | Q25: n/a | R25: n/a
A26: 78 | B26: 2020[ReAg][pts]3[ION]1 | C26: 0.10592392 | D26: -0.021396946 | E26: 0.099557021 | F26: =MID(B26,6,P26-6) -> ReAg | G26: pts | H26: 1.87154 | I26: 2.2934 | J26: 4.48602 | K26: 3523.71 | L26: 0.4365 | M26: 0.23323 | N26: 812.724 | P26: =FIND("]",B26) -> 10 | Q26: n/a | R26: n/a
A27: 97 | B27: 2023[GaNi][cds]3[ION]1 | C27: 0.014239387 | D27: -0.04499165 | E27: 0.3423655 | F27: =MID(B27,6,P27-6) -> GaNi | G27: cds | H27: 0.854661 | I27: 5.11275 | J27: 7.93398 | K27: 4801.3 | L27: 0.62918 | M27: 0.736175 | N27: 8470.52 | P27: =FIND("]",B27) -> 10
A28: 1 | B28: 2009[Zn][sql]2[ION]1 | C28: -0.033760226 | D28: -0.060986825 | E28: 0.32796159 | F28: =MID(B28,6,P28-6) -> Zn | G28: sql | H28: 0.883366 | I28: 4.40897 | J28: 7.92601 | K28: 5260.41 | L28: 0.60494 | M28: 0.684813 | N28: 1683.308 | P28: =FIND("]",B28) -> 8
A29: 100 | B29: 2024[Cd][hcb]2[ION]1 | C29: -0.029070191 | D29: -0.077889494 | E29: 0.32943952 | F29: =MID(B29,6,P29-6) -> Cd | G29: hcb | H29: 0.932106 | I29: 3.675 | J29: 6.53373 | K29: 5102.82 | L29: 0.63438 | M29: 0.680588 | N29: 1850.98 | P29: =FIND("]",B29) -> 8
A30: 39 | B30: 2018[Tb][kgd]2[ION]1 | C30: 0.10643217 | D30: -0.089998163 | E30: 0.090531167 | F30: =MID(B30,6,P30-6) -> Tb | G30: kgd | H30: 1.72 | I30: 2.70519 | J30: 3.97658 | K30: 3564 | L30: 0.43284 | M30: 0.251651 | N30: 987.22 | P30: =FIND("]",B30) -> 8
A31: 36 | B31: 2018[Dy][kgd]2[ION]1 | C31: 0.10917798 | D31: -0.091110547 | E31: 0.090720951 | F31: =MID(B31,6,P31-6) -> Dy | G31: kgd | H31: 1.72972 | I31: 2.5891 | J31: 4.23845 | K31: 3559.54 | L31: 0.42908 | M31: 0.248063 | N31: 673.402 | P31: =FIND("]",B31) -> 8
A32: 50 | B32: 2019[Eu][flu]3[ION]1 | C32: 0.089238488 | D32: -0.11392699 | E32: 0.29138433 | F32: =MID(B32,6,P32-6) -> Eu | G32: flu | H32: 1.24605 | I32: 6.32609 | J32: 7.02294 | K32: 4115.42 | L32: 0.54276 | M32: 0.435584 | N32: 1746.726 | P32: =FIND("]",B32) -> 8
A33: 60 | B33: 2019[Sm][flu]3[ION]1 | C33: 0.09452145 | D33: -0.12630256 | E33: 0.28748435 | F33: =MID(B33,6,P33-6) -> Sm | G33: flu | H33: 1.25972 | I33: 6.14509 | J33: 7.08004 | K33: 4104.57 | L33: 0.53942 | M33: 0.428205 | N33: 1442.798 | P33: =FIND("]",B33) -> 8
A34: 38 | B34: 2018[Gd][kgd]2[ION]1 | C34: 0.10742296 | D34: -0.14324535 | E34: 0.081345569 | F34: =MID(B34,6,P34-6) -> Gd | G34: kgd | H34: 1.73173 | I34: 2.5676 | J34: 3.93796 | K34: 3582.16 | L34: 0.42522 | M34: 0.245547 | N34: 673.402 | P34: =FIND("]",B34) -> 8
A35: 70 | B35: 2019[Yb][sqc]3[ION]1 | C35: 0.11196074 | D35: -0.1516933 | E35: 0.22666735 | F35: =MID(B35,6,P35-6) -> Yb | G35: sqc | H35: 1.42531 | I35: 5.45574 | J35: 6.45783 | K35: 3891.2 | L35: 0.4933 | M35: 0.3461 | N35: 1442.798 | P35: =FIND("]",B35) -> 8
A36: 57 | B36: 2019[Nd][flu]3[ION]1 | C36: 0.097352839 | D36: -0.17661636 | E36: 0.28221365 | F36: =MID(B36,6,P36-6) -> Nd | G36: flu | H36: 1.23327 | I36: 5.74228 | J36: 6.78156 | K36: 4152.28 | L36: 0.54546 | M36: 0.442289 | N36: 1442.798 | P36: =FIND("]",B36) -> 8
A37: 99 | B37: 2023[U][hcb]2[ION]1 | C37: 0.098354607 | D37: -0.220857 | E37: 0.056926967 | F37: =MID(B37,6,P37-6) -> U | G37: hcb | H37: 1.95256 | I37: 2.21966 | J37: 3.34285 | K37: 3594.96 | L37: 0.41178 | M37: 0.210893 | N37: 1409.184 | P37: =FIND("]",B37) -> 7
A38: 75 | B38: 2020[Cu][sql]2[ION]1 | C38: -0.025143868 | D38: -0.24325487 | E38: 0.28284671 | F38: =MID(B38,6,P38-6) -> Cu | G38: sql | H38: 1.01354 | I38: 4.27647 | J38: 5.50048 | K38: 5376.98 | L38: 0.55228 | M38: 0.544902 | N38: 2292.1 | P38: =FIND("]",B38) -> 8
... A100: 68 | B100: 2019[Y][sqc]3[ION]1 | C100: 0.13602734 | D100: -1.0594733 | E100: 0.12294165 | F100: =MID(B100,6,P100-6) -> Y | G100: sqc | H100: 1.40393 | I100: 3.6031 | J100: 5.51268 | K100: 4710.61 | L100: 0.39856 | M100: 0.28389 | N100: 1495.206 | P100: =FIND("]",B100) -> 7
A101: 48 | B101: 2019[Cu][sql]2[ION]1 | C101: 0.14925258 | D101: -1.0916486 | E101: 0.099557041 | F101: =MID(B101,6,P101-6) -> Cu | G101: sql | H101: 1.44613 | I101: 2.94298 | J101: 4.75381 | K101: 4550.02 | L101: 0.40488 | M101: 0.279975 | N101: 1360.082 | P101: =FIND("]",B101) -> 8 | Q101: n/a | R101: n/a
A102: 30 | B102: 2017[In][kgd]2[ION]1 | C102: 0.14757322 | D102: -1.1006208 | E102: 0.085558476 | F102: =MID(B102,6,P102-6) -> In | G102: kgd | H102: 1.49968 | I102: 3.11886 | J102: 4.87876 | K102: 4467.34 | L102: 0.38342 | M102: 0.255668 | N102: 4874.364 | P102: =FIND("]",B102) -> 8 | Q102: n/a | R102: n/a

Sheet NCR_BatchB
E1: =MAX(E3:E3694) -> 0.90035121
A2: Serial | B2: name | C2: OCSVM (nu=0.15) | D2: SVM(C=1.0) | E2: SVR(C=1.0) | F2: Density | G2: PLD | H2: LCD | I2: GSA | J2: Void_Fraction | K2: Pore_Volume | L2: UnitCell_MW_g_mol | O2: min (energy) | P2: max (energy) | Q2: center of range | R2: goodness coefficient (normalized by the center of the best range)
A3: 2773 | B3: ic6b02413_si_002_2_FSR_pacman | C3: 0.050271001 | D3: 1.4364215 | E3: 0.42845444 | F3: 0.989594 | G3: 5.93433 | H3: 13.64653 | I3: 2799.06 | J3: 0.70388 | K3: 0.711282 | L3: 9956.496 | O3: -19.5 | P3: -19.44 | Q3: =O3+(P3-O3)/2 -> -19.47 | R3: =Q3/(-37.73) -> 0.51603499
A4: 2772 | B4: ic6b02413_si_002_2_ASR_pacman | C4: 0.050271001 | D4: 1.4364215 | E4: 0.42845444 | F4: 0.989594 | G4: 5.93433 | H4: 13.64653 | I4: 2799.06 | J4: 0.70388 | K4: 0.711282 | L4: 9956.496 | O4: -19.97 | P4: -19.91 | Q4: =O4+(P4-O4)/2 -> -19.94 | R4: =Q4/(-37.73) -> 0.52849192
A5: 2959 | B5: ja510525s_si_002_FSR_pacman | C5: 0.066805477 | D5: 1.4358527 | E5: 0.42414599 | F5: 1.08186 | G5: 5.07236 | H5: 12.04251 | I5: 2832.29 | J5: 0.67468 | K5: 0.623629 | L5: 3084.225 | O5: -28.08 | P5: -28 | Q5: =O5+(P5-O5)/2 -> -28.04 | R5: =Q5/(-37.73) -> 0.74317519
A6: 2958 | B6: ja510525s_si_002_ASR_pacman | C6: 0.066805477 | D6: 1.4358527 | E6: 0.42414599 | F6: 1.08186 | G6: 5.07236 | H6: 12.04251 | I6: 2832.29 | J6: 0.67468 | K6: 0.623629 | L6: 3084.225 | O6: -27.99 | P6: -27.93 | Q6: =O6+(P6-O6)/2 -> -27.96 | R6: =Q6/(-37.73) -> 0.74105486
A7: 2147 | B7: d1dt02515e2_1_FSR_pacman | C7: 0.036764379 | D7: 1.4316321 | E7: 0.39148316 | F7: 1.13211 | G7: 6.42748 | H7: 9.60663 | I7: 2838.88 | J7: 0.69104 | K7: 0.610402 | L7: 2453.572
A8: 2258 | B8: d2cc03575h2_FSR_pacman | C8: 0.067740131 | D8: 1.4311083 | E8: 0.44056069 | F8: 0.86656 | G8: 9.73342 | H8: 17.00966 | I8: 3055.67 | J8: 0.72274 | K8: 0.834033 | L8: 3361.015
A9: 2146 | B9: d1dt02515e2_1_ASR_pacman | C9: 0.026753175 | D9: 1.4294824 | E9: 0.39060607 | F9: 1.10934 | G9: 6.62749 | H9: 9.91169 | I9: 2781.58 | J9: 0.70092 | K9: 0.631833 | L9: 2389.576
A10: 3551 | B10: ja9b06711_si_003_ASR_pacman | C10: 0.024859213 | D10: 1.4286674 | E10: 0.39531775 | F10: 0.889411 | G10: 7.43761 | H10: 12.69089 | I10: 3024.68 | J10: 0.73608 | K10: 0.827604 | L10: 7275.462
A11: 2991 | B11: ja512311a_si_010_ASR_pacman | C11: 0.029629475 | D11: 1.424144 | E11: 0.39606314 | F11: 0.865416 | G11: 7.69561 | H11: 11.54469 | I11: 3058.76 | J11: 0.71776 | K11: 0.829382 | L11: 10016.515
A12: 2992 | B12: ja512311a_si_010_FSR_pacman | C12: 0.029629475 | D12: 1.424144 | E12: 0.39606314 | F12: 0.865416 | G12: 7.69561 | H12: 11.54469 | I12: 3058.76 | J12: 0.71776 | K12: 0.829382 | L12: 10016.515
A13: 3283 | B13: ja7b09496_si_008_FSR_pacman | C13: 0.020176222 | D13: 1.4227965 | E13: 0.3909049 | F13: 1.03544 | G13: 8.11403 | H13: 9.87101 | I13: 2870.93 | J13: 0.70702 | K13: 0.682818 | L13: 3582.708
A14: 2305 | B14: d2dt04043c2_ASR_pacman | C14: 0.094684651 | D14: 1.4215959 | E14: 0.47721764 | F14: 1.15751 | G14: 9.30686 | H14: 13.99382 | I14: 2941.89 | J14: 0.64294 | K14: 0.555451 | L14: 9474.608
A15: 1656 | B15: cm6b02817_si_003_FSR_pacman | C15: 0.084665955 | D15: 1.4204053 | E15: 0.41039449 | F15: 1.38426 | G15: 5.71864 | H15: 10.61307 | I15: 2695.68 | J15: 0.63692 | K15: 0.460117 | L15: 7949.696
A16: 1655 | B16: cm6b02817_si_003_ASR_pacman | C16: 0.084665955 | D16: 1.4204053 | E16: 0.41039449 | F16: 1.38426 | G16: 5.71864 | H16: 10.61307 | I16: 2695.68 | J16: 0.63692 | K16: 0.460117 | L16: 7949.696
A17: 646 | B17: c6ta10785k2_2_ASR_pacman | C17: 0.048767082 | D17: 1.4200715 | E17: 0.39333649 | F17: 1.07093 | G17: 5.11171 | H17: 9.81496 | I17: 2858.22 | J17: 0.67322 | K17: 0.628633 | L17: 2139.144
A18: 647 | B18: c6ta10785k2_2_FSR_pacman | C18: 0.048767082 | D18: 1.4200715 | E18: 0.39333649 | F18: 1.07093 | G18: 5.11171 | H18: 9.81496 | I18: 2858.22 | J18: 0.67322 | K18: 0.628633 | L18: 2139.144
... A1710: 2346 | B1710: d2sc00188h2_5_FSR_pacman | C1710: 0.074754346 | D1710: 0.80047145 | E1710: 0.40234781 | F1710: 1.05079 | G1710: 6.99847 | H1710: 9.55353 | I1710: 3753.45 | J1710: 0.63124 | K1710: 0.600728 | L1710: 3791.202
A1711: 3652 | B1711: jp8b09178_si_007_FSR_pacman | C1711: -0.0059620678 | D1711: 0.79914751 | E1711: 0.41074078 | F1711: 0.487583 | G1711: 28.06898 | H1711: 29.87417 | I1711: 3411.27 | J1711: 0.8299 | K1711: 1.70207 | L1711: 6733.38 | O1711: -11.79 | P1711: -11.66 | Q1711: =O1711+(P1711-O1711)/2 -> -11.725 | R1711: =Q1711/(-37.73) -> 0.31076067
A1712: 3651 | B1712: jp8b09178_si_007_ASR_pacman | C1712: -0.0059620678 | D1712: 0.79914751 | E1712: 0.41074078 | F1712: 0.487583 | G1712: 28.06898 | H1712: 29.87417 | I1712: 3411.27 | J1712: 0.8299 | K1712: 1.70207 | L1712: 6733.38 | O1712: -16.05 | P1712: -15.97 | Q1712: =O1712+(P1712-O1712)/2 -> -16.01 | R1712: =Q1712/(-37.73) -> 0.42433077
A1713: 3456 | B1713: ja8b12530_si_001_3_FSR_pacman | C1713: -0.051475332 | D1713: 0.7984196 | E1713: 0.43128795 | F1713: 0.534284 | G1713: 29.3367 | H1713: 30.79071 | I1713: 3455.04 | J1713: 0.80936 | K1713: 1.51485 | L1713: 6457.719 | O1713: -13.87 | P1713: -13.77 | Q1713: =O1713+(P1713-O1713)/2 -> -13.82 | R1713: =Q1713/(-37.73) -> 0.36628677
A1714: 2874 | B1714: ja0c10367_si_003_ASR_pacman | C1714: -0.25164298 | D1714: 0.79767968 | E1714: 0.70551347 | F1714: 0.634898 | G1714: 29.24165 | H1714: 29.81015 | I1714: 2745.12 | J1714: 0.81732 | K1714: 1.28732 | L1714: 6417 | O1714: -34.18 | P1714: -34.12 | Q1714: =O1714+(P1714-O1714)/2 -> -34.15 | R1714: =Q1714/(-37.73) -> 0.90511529
A1715: 1671 | B1715: cm9b01258_si_005_FSR_pacman | C1715: -0.20383901 | D1715: 0.79764353 | E1715: 0.34902047 | F1715: 2.57038 | G1715: 3.72007 | H1715: 8.3558 | I1715: 1519.78 | J1715: 0.47636 | K1715: 0.185327 | L1715: 4842.024
A1716: 802 | B1716: c7dt02231j2_2_FSR_pacman | C1716: 0.051466871 | D1716: 0.79755888 | E1716: 0.40381055 | F1716: 1.00472 | G1716: 7.66578 | H1716: 9.38848 | I1716: 3823.59 | J1716: 0.64704 | K1716: 0.643997 | L1716: 10248.544
A1717: 2852 | B1717: ja0c07081_si_004_ASR_pacman | C1717: -0.25401642 | D1717: 0.79681393 | E1717: 0.55507386 | F1717: 0.791145 | G1717: 16.17958 | H1717: 22.3583 | I1717: 2092.26 | J1717: 0.78832 | K1717: 0.996429 | L1717: 3702.272
A1718: 1259 | B1718: c8ta02794c2_2_ASR_pacman | C1718: 0.056607458 | D1718: 0.79653689 | E1718: 0.13666703 | F1718: 1.91474 | G1718: 3.73243 | H1718: 3.95711 | I1718: 2867.45 | J1718: 0.4268 | K1718: 0.222902 | L1718: 1834.568
A1719: 633 | B1719: c6sc05012c2_FSR_pacman | C1719: -0.031669107 | D1719: 0.7955919 | E1719: 0.13793729 | F1719: 2.08763 | G1719: 3.12468 | H1719: 3.97172 | I1719: 2554.43 | J1719: 0.34368 | K1719: 0.164627 | L1719: 332.861
A1720: 632 | B1720: c6sc05012c2_ASR_pacman | C1720: -0.031669107 | D1720: 0.7955919 | E1720: 0.13793729 | F1720: 2.08763 | G1720: 3.12468 | H1720: 3.97172 | I1720: 2554.43 | J1720: 0.34368 | K1720: 0.164627 | L1720: 332.861
A1721: 1233 | B1721: c8qm00105g2_ASR_pacman | C1721: 0.065720228 | D1721: 0.79539797 | E1721: 0.40486142 | F1721: 0.9892 | G1721: 3.86632 | H1721: 10.47726 | I1721: 3757.18 | J1721: 0.65536 | K1721: 0.662515 | L1721: 1714.137
A1722: 889 | B1722: c7qi00615b2_2_ASR_pacman | C1722: 0.082514224 | D1722: 0.79533908 | E1722: 0.33848664 | F1722: 1.17943 | G1722: 7.10527 | H1722: 7.22899 | I1722: 3464.79 | J1722: 0.56564 | K1722: 0.479586 | L1722: 988.193
A1723: 890 | B1723: c7qi00615b2_2_FSR_pacman | C1723: 0.082514224 | D1723: 0.79533908 | E1723: 0.33848664 | F1723: 1.17943 | G1723: 7.10527 | H1723: 7.22899 | I1723: 3464.79 | J1723: 0.56564 | K1723: 0.479586 | L1723: 988.193
A1724: 3455 | B1724: ja8b12530_si_001_3_ASR_pacman | C1724: -0.047864064 | D1724: 0.79476564 | E1724: 0.43760565 | F1724: 0.519576 | G1724: 29.3367 | H1724: 30.79071 | I1724: 3415.84 | J1724: 0.81526 | K1724: 1.56909 | L1724: 6265.731
A1725: 391 | B1725: am9b14121_si_001_1_ASR_pacman | C1725: 0.037785419 | D1725: 0.79063522 | E1725: 0.3802717 | F1725: 0.954122 | G1725: 4.82287 | H1725: 8.27019 | I1725: 3760.46 | J1725: 0.66612 | K1725: 0.69815 | L1725: 10231.784
A1726: 371 | B1726: am9b00872_si_002_ASR_pacman | C1726: -0.22898624 | D1726: 0.78930873 | E1726: 0.30833118 | F1726: 3.47669 | G1726: 3.71172 | H1726: 5.09899 | I1726: 1572.68 | J1726: 0.43944 | K1726: 0.126396 | L1726: 1571.588
... A3692: 822 | B3692: c7dt02800h2_3_ion_pacman | C3692: 0.13217943 | D3692: -1.1265725 | E3692: 0.06860342 | F3692: 1.51855 | G3692: 1.30531 | H3692: 2.85036 | I3692: 4680.54 | J3692: 0.37134 | K3692: 0.244535 | L3692: 8595.6
A3693: 580 | B3693: c6ce00407e7_ASR_pacman | C3693: -0.77771405 | D3693: -1.1556822 | E3693: 0.90035121 | F3693: 0.207465 | G3693: 15.95479 | H3693: 33.68342 | I3693: 4888.62 | J3693: 0.90886 | K3693: 4.3808 | L3693: 10846.176 | O3693: -37.75 | P3693: -37.71 | Q3693: =O3693+(P3693-O3693)/2 -> -37.73 | R3693: =Q3693/(-37.73) -> 1
A3694: 581 | B3694: c6ce00407e7_FSR_pacman | C3694: -0.77771405 | D3694: -1.1556822 | E3694: 0.90035121 | F3694: 0.207465 | G3694: 15.95479 | H3694: 33.68342 | I3694: 4888.62 | J3694: 0.90886 | K3694: 4.3808 | L3694: 10846.176 | O3694: -37.62 | P3694: -37.62 | Q3694: =O3694+(P3694-O3694)/2 -> -37.62 | R3694: =Q3694/(-37.73) -> 0.99708455

Sheet Occupancy_BatchB
E1: =MAX(E3:E311) -> 0.4917269
A2: Serial | B2: name | C2: OCSVM (nu=0.15) | D2: SVM(C=1.0) | E2: SVR(C=1.0) | F2: Density | G2: PLD | H2: LCD | I2: GSA | J2: Void_Fraction | K2: Pore_Volume | L2: UnitCell_MW_g_mol | O2: min (energy) | P2: max (energy) | Q2: center of range | R2: goodness coefficient (normalized by the center of the best range)
A3: 254 | B3: ja7b04532_si_002_FSR_pacman | C3: 0.069003863 | D3: 1.4515926 | E3: 0.44056351 | F3: 0.996126 | G3: 7.37756 | H3: 14.79124 | I3: 2908.87 | J3: 0.70926 | K3: 0.712018 | L3: 1985.016 | O3: -8.923 | P3: -7.042 | Q3: =O3+(P3-O3)/2 -> -7.9825 | R3: =Q3/(-37.73) -> 0.21156904
A4: 38 | B4: c5dt03091a2_2_FSR_pacman | C4: 0.065277877 | D4: 1.3863938 | E4: 0.42444978 | F4: 0.941723 | G4: 7.05673 | H4: 13.1277 | I4: 3276.1 | J4: 0.70936 | K4: 0.753257 | L4: 8743.968 | O4: -13.75 | P4: -11.25 | Q4: =O4+(P4-O4)/2 -> -12.5 | R4: =Q4/(-37.73) -> 0.33130135
A5: 39 | B5: c5dt03091a2_3_FSR_pacman | C5: 0.068919133 | D5: 1.3792128 | E5: 0.42710107 | F5: 0.9378 | G5: 7.21319 | H5: 13.22023 | I5: 3297.81 | J5: 0.70628 | K5: 0.753124 | L5: 14342.912
A6: 37 | B6: c5dt03091a2_1_FSR_pacman | C6: 0.054162437 | D6: 1.3197009 | E6: 0.41597997 | F6: 0.877341 | G6: 7.45136 | H6: 13.4706 | I6: 3442.79 | J6: 0.7207 | K6: 0.821459 | L6: 8743.968
A7: 238 | B7: ja205976v_si_004_ASR_pacman | C7: 0.085978498 | D7: 1.3179839 | E7: 0.3683493 | F7: 1.40681 | G7: 7.6745 | H7: 8.85712 | I7: 2623.34 | J7: 0.55644 | K7: 0.395532 | L7: 3328.056
A8: 239 | B8: ja205976v_si_004_FSR_pacman | C8: 0.085978498 | D8: 1.3179839 | E8: 0.3683493 | F8: 1.40681 | G8: 7.6745 | H8: 8.85712 | I8: 2623.34 | J8: 0.55644 | K8: 0.395532 | L8: 3328.056
A9: 297 | B9: ja9b11429_si_002_FSR_pacman | C9: -0.018971734 | D9: 1.2757882 | E9: 0.34255336 | F9: 0.623695 | G9: 9.40509 | H9: 17.56744 | I9: 3244.1 | J9: 0.78866 | K9: 1.2645 | L9: 2482.218
A10: 253 | B10: ja7b04532_si_002_ASR_pacman | C10: -0.052723292 | D10: 1.2638774 | E10: 0.39056222 | F10: 0.83887 | G10: 7.37756 | H10: 16.49393 | I10: 2603.17 | J10: 0.7771 | K10: 0.926365 | L10: 1473.048
A11: 110 | B11: c9cc08206a2_2_ASR_pacman | C11: 0.054736364 | D11: 1.2314137 | E11: 0.28043087 | F11: 1.7134 | G11: 5.52643 | H11: 6.05033 | I11: 2498.57 | J11: 0.52184 | K11: 0.304563 | L11: 3112.888
A12: 296 | B12: ja9b11429_si_002_ASR_pacman | C12: -0.024603261 | D12: 1.2200645 | E12: 0.33214393 | F12: 0.606688 | G12: 9.40509 | H12: 17.56744 | I12: 3382.65 | J12: 0.79454 | K12: 1.30963 | L12: 2386.224
A13: 287 | B13: ja9b04737_si_006_FSR_pacman | C13: -0.063852469 | D13: 1.2199454 | E13: 0.42793917 | F13: 0.980555 | G13: 13.44814 | H13: 13.97389 | I13: 2691.39 | J13: 0.7489 | K13: 0.763751 | L13: 2786.104
A14: 268 | B14: ja7b09973_si_002_2_ASR_pacman | C14: -0.067275233 | D14: 1.2165157 | E14: 0.35030863 | F14: 0.656444 | G14: 8.05787 | H14: 11.5693 | I14: 3460.46 | J14: 0.76304 | K14: 1.16238 | L14: 2064.544
A15: 205 | B15: d2sc05192c2_ASR_pacman | C15: 0.079794916 | D15: 1.2114775 | E15: 0.34361343 | F15: 1.29084 | G15: 4.02108 | H15: 7.57139 | I15: 3040.72 | J15: 0.60486 | K15: 0.468578 | L15: 7132.368
A16: 258 | B16: ja7b04532_si_005_ASR_pacman | C16: -0.016896572 | D16: 1.2106488 | E16: 0.37629027 | F16: 0.759131 | G16: 8.1262 | H16: 10.97432 | I16: 3544.89 | J16: 0.74078 | K16: 0.975827 | L16: 6157.816
... A211: 179 | B211: d0dt00794c2_2_FSR_pacman | C211: 0.1014443 | D211: 0.021941264 | E211: 0.28686237 | F211: 1.17786 | G211: 5.11422 | H211: 6.61424 | I211: 3981.38 | J211: 0.55558 | K211: 0.471686 | L211: 4675.856
A212: 2 | B212: am0c02121_si_002_1_ion_pacman | C212: 0.11478531 | D212: 0.0064579471 | E212: 0.15270103 | F212: 1.58823 | G212: 4.40283 | H212: 5.38384 | I212: 3600.39 | J212: 0.44992 | K212: 0.283284 | L212: 1108.88 | O212: n/a | P212: n/a
A213: 167 | B213: d0cc03472j2_2_ASR_pacman | C213: 0.11332824 | D213: -0.0042416185 | E213: 0.2026952 | F213: 1.5636 | G213: 5.40258 | H213: 6.81956 | I213: 3688.02 | J213: 0.45864 | K213: 0.293323 | L213: 2366.396 | O213: -20.51 | P213: -17.47 | Q213: =O213+(P213-O213)/2 -> -18.99 | R213: =Q213/(-37.73) -> 0.50331301
A214: 168 | B214: d0cc03472j2_2_FSR_pacman | C214: 0.11332824 | D214: -0.0042416185 | E214: 0.2026952 | F214: 1.5636 | G214: 5.40258 | H214: 6.81956 | I214: 3688.02 | J214: 0.45864 | K214: 0.293323 | L214: 2366.396
A215: 158 | B215: cm0c01737_si_005_117_FSR_pacman | C215: 0.059269126 | D215: -0.017289613 | E215: 0.2703059 | F215: 1.33062 | G215: 4.42216 | H215: 4.54354 | I215: 4014.72 | J215: 0.58206 | K215: 0.437435 | L215: 610.422
A216: 157 | B216: cm0c01737_si_005_117_ASR_pacman | C216: 0.059269126 | D216: -0.017289613 | E216: 0.2703059 | F216: 1.33062 | G216: 4.42216 | H216: 4.54354 | I216: 4014.72 | J216: 0.58206 | K216: 0.437435 | L216: 610.422
A217: 46 | B217: c6qi00548a2_ASR_pacman | C217: 0.076146363 | D217: -0.019472828 | E217: 0.31428352 | F217: 1.03097 | G217: 6.05589 | H217: 6.78911 | I217: 4192.98 | J217: 0.579 | K217: 0.561604 | L217: 1995.624
A218: 47 | B218: c6qi00548a2_FSR_pacman | C218: 0.076146363 | D218: -0.019472828 | E218: 0.31428352 | F218: 1.03097 | G218: 6.05589 | H218: 6.78911 | I218: 4192.98 | J218: 0.579 | K218: 0.561604 | L218: 1995.624
A219: 90 | B219: c8dt03215g2_2_ASR_pacman | C219: 0.059484618 | D219: -0.032115385 | E219: 0.35744112 | F219: 0.96161 | G219: 5.45153 | H219: 10.61906 | I219: 4715.54 | J219: 0.60448 | K219: 0.628612 | L219: 7096.29
A220: 91 | B220: c8dt03215g2_2_FSR_pacman | C220: 0.059484618 | D220: -0.032115385 | E220: 0.35744112 | F220: 0.96161 | G220: 5.45153 | H220: 10.61906 | I220: 4715.54 | J220: 0.60448 | K220: 0.628612 | L220: 7096.29
A221: 88 | B221: c8dt01405a2_2_ASR_pacman | C221: 0.087369049 | D221: -0.037462267 | E221: 0.30158857 | F221: 1.10099 | G221: 3.72517 | H221: 6.64119 | I221: 4138.22 | J221: 0.58938 | K221: 0.535316 | L221: 2452.944
A222: 89 | B222: c8dt01405a2_2_FSR_pacman | C222: 0.087369049 | D222: -0.037462267 | E222: 0.30158857 | F222: 1.10099 | G222: 3.72517 | H222: 6.64119 | I222: 4138.22 | J222: 0.58938 | K222: 0.535316 | L222: 2452.944
A223: 4 | B223: am0c02121_si_002_3_ion_pacman | C223: 0.11287889 | D223: -0.041339457 | E223: 0.10617995 | F223: 1.65838 | G223: 3.01201 | H223: 4.55854 | I223: 3551.15 | J223: 0.43438 | K223: 0.261931 | L223: 1108.88
A224: 175 | B224: d0ce01197e2_1_ASR_pacman | C224: 0.11403151 | D224: -0.0426435 | E224: 0.19898461 | F224: 1.54641 | G224: 4.37879 | H224: 5.62379 | I224: 3750.57 | J224: 0.4936 | K224: 0.319191 | L224: 1306.354
A225: 31 | B225: c5ce02367j2_1_ASR_pacman | C225: 0.088364936 | D225: -0.048264231 | E225: 0.28687025 | F225: 1.32651 | G225: 6.71642 | H225: 7.36648 | I225: 3994.82 | J225: 0.52228 | K225: 0.393726 | L225: 17480.784
... A309: 230 | B309: ic801404p_si_001_FSR_pacman | C309: 0.14486325 | D309: -1.0011692 | E309: 0.13634909 | F309: 1.28047 | G309: 2.53121 | H309: 4.93564 | I309: 4665.44 | J309: 0.44772 | K309: 0.349652 | L309: 1412.85
A310: 36 | B310: c5dt00480b2_3_ion_pacman | C310: 0.12193653 | D310: -1.0263261 | E310: 0.13178358 | F310: 1.41256 | G310: 4.51007 | H310: 4.85912 | I310: 4682.98 | J310: 0.4159 | K310: 0.294431 | L310: 1092.816 | O310: n/a | P310: n/a
A311: 98 | B311: c8ra02809e2_ion_pacman | C311: 0.14470127 | D311: -1.1172441 | E311: 0.08330346 | F311: 1.50505 | G311: 2.95617 | H311: 4.03544 | I311: 4532.4 | J311: 0.39272 | K311: 0.260936 | L311: 7148.336 | O311: n/a | P311: n/a

Sheet Stage2EnergyScores
A1: Serial | B1: Name | C1: SVM (C=1.0) | D1: Normalised EnergyScore | E1: PLD | F1: LCD | G1: GSA | H1: Void_Fraction | I1: Pore_Volume | J1: UnitCell_MW_g_mol
A2: 1 | B2: 2022[Zr][lvt]3[ASR]1 | C2: 1.43641 | D2: 0.37993639 | E2: 6.93 | F2: 9.83 | G2: 2836.58 | H2: 0.67 | I2: 0.63 | J2: 5783.264
A3: 6 | B3: 2021[Hf][sqc]3[FSR]1 | C3: 1.4145043 | D3: 0.27391996 | E3: 5.24898 | F3: 9.19603 | G3: 2701.41 | H3: 0.66564 | I3: 0.55315 | J3: 4928.176
A4: 7 | B4: 2021[Eu][fcu]3[FSR]1 | C4: 1.4067707 | D4: 0.34852902 | E4: 7.21484 | F4: 13.70548 | G4: 3102.54 | H4: 0.7491 | I4: 0.91406 | J4: 2600.766
A5: 8 | B5: 2016[Tb][fcu]3[FSR]1 | C5: 1.4058074 | D5: 0.28756957 | E5: 6.94679 | F5: 13.37735 | G5: 3091.16 | H5: 0.74496 | I5: 0.926251 | J5: 2530.89
A6: 9 | B6: 2021[Th][fcu]3[FSR]1 | C6: 1.404015 | D6: 0.26973231 | E6: 7.11938 | F6: 13.67888 | G6: 2784.83 | H6: 0.7428 | I6: 0.79765 | J6: 1665.27
A7: 10 | B7: 2024[Tb][tfz]3[FSR]1 | C7: 1.3998402 | D7: 0.28917307 | E7: 8.8743 | F7: 9.7381 | G7: 2787.98 | H7: 0.70794 | I7: 0.700382 | J7: 4693.076
A8: 2 | B8: 2020[Zn][nan]3[ASR]16 | C8: 1.34962 | D8: 0.34760138 | E8: 11.01 | F8: 11.72 | G8: 2699.02 | H8: 0.67 | I8: 0.55 | J8: 974.574
A9: 3 | B9: 2023[La][pts]3[ASR]1 | C9: 1.3271849 | D9: 0.55115293 | E9: 7.5 | F9: 8.09 | G9: 3001.63 | H9: 0.62 | I9: 0.51 | J9: 870.198
A10: 4 | B10: 2017[Co][nan]3[ASR]5 | C10: 1.2152885 | D10: 0.22895574 | E10: 5.76 | F10: 7.7 | G10: 2945.36 | H10: 0.56 | I10: 0.41 | J10: 1103.976
A11: 15 | B11: 2018[ZnMo][qtz]3[ION]2 | C11: 1.1813023 | D11: 0.27209117 | E11: 3.78303 | F11: 6.0504 | G11: 2445.48 | H11: 0.50178 | I11: 0.241323 | J11: 3986.976
A12: 16 | B12: 2018[ZnMo][qtz]3[ION]1 | C12: 1.1813023 | D12: 0.15625497 | E12: 3.78303 | F12: 6.0504 | G12: 2445.48 | H12: 0.50178 | I12: 0.241323 | J12: 3986.976
A13: 5 | B13: 2018[Ce][csq]3[ASR]1 | C13: 1.0988809 | D13: 0.33249404 | E13: 17.74 | F13: 23.52 | G13: 3476.89 | H13: 0.81 | I13: 1.44 | J13: 5452.68
... A21: 14 | B21: 2017[Ni][hms]3[FSR]1 | C21: -1.1367094 | D21: 0 | E21: 2.34169 | F21: 3.06322 | G21: 4474.05 | H21: 0.37466 | I21: 0.245802 | J21: 2531.988

Sheet Stage2EnergyNTopology
A1: Serial | B1: Name | C1: SVM | D1: Metal | E1: Metal | F1: Topology | G1: Density | H1: PLD | I1: LCD | J1: GSA | K1: Void_Fraction | L1: Pore_Volume | M1: UnitCell_MW_g_mol | N1: EnergyScore
A2: 1 | B2: 2022[Zr][lvt]3[ASR]1 | D2: Zr | E2: Zr | F2: Ivt | G2: 1.07 | H2: 6.93 | I2: 9.83 | J2: 2836.58 | K2: 0.67 | L2: 0.63 | M2: 5783.264 | N2: 0.37993639
A3: 2 | B3: 2020[Zn][nan]3[ASR]16 | D3: Zn | E3: Zn | F3: nan | G3: 1.21 | H3: 11.01 | I3: 11.72 | J3: 2699.02 | K3: 0.67 | L3: 0.55 | M3: 974.574 | N3: 0.34760138
A4: 3 | B4: 2023[La][pts]3[ASR]1 | D4: La | E4: La | F4: pts | G4: 1.21 | H4: 7.5 | I4: 8.09 | J4: 3001.63 | K4: 0.62 | L4: 0.51 | M4: 870.198 | N4: 0.55115293
A5: 4 | B5: 2017[Co][nan]3[ASR]5 | D5: Co | E5: Co | F5: nan | G5: 1.38 | H5: 5.76 | I5: 7.7 | J5: 2945.36 | K5: 0.56 | L5: 0.41 | M5: 1103.976 | N5: 0.22895574
A6: 5 | B6: 2018[Ce][csq]3[ASR]1 | D6: Ce | E6: Ce | F6: csq | G6: 0.56 | H6: 17.74 | I6: 23.52 | J6: 3476.89 | K6: 0.81 | L6: 1.44 | M6: 5452.68 | N6: 0.33249404
A7: 6 | B7: 2021[Hf][sqc]3[FSR]1 | D7: Hf | E7: Hf | F7: sqc | G7: 1.20336 | H7: 5.24898 | I7: 9.19603 | J7: 2701.41 | K7: 0.66564 | L7: 0.55315 | M7: 4928.176 | N7: 0.27391996
